Workbook

Sheet Sheet1
A1: id【KEY】 | B1: 注释字段 | C1: 下一节点id | D1: 所属波次 | E1: 刷怪时间s | F1: 持续刷怪时间 | G1: 事件0战斗开始 1BOSS 2敌群 | H1: 波次生命系数 | I1: 波次攻击系数 | J1: 刷怪（频率，数量，重复出现，怪物形象id，刷怪方式）
A2: both | C2: both | D2: client | E2: client | F2: client | G2: client | H2: client | I2: client | J2: both
A3: id | B3: string | C3: nextId | D3: nowWave | E3: time | F3: gringTime | G3: incident | H3: hpCoefficient | I3: atkCoefficient | J3: summon
A4: int | B4: string | C4: int | D4: int | E4: int | F4: int | G4: int | H4: int | I4: int | J4: [Grinding]
D5: index
A6: 1 | B6: 每日挑战 | C6: 2 | D6: 1 | E6: 1 | F6: 3000 | H6: 5000 | I6: 2000 | J6: [{1000,1,1,-1,-1}]
A7: 2 | B7: 每日挑战 | C7: 3 | D7: 1 | E7: 3 | F7: 4000 | H7: 5000 | I7: 2000 | J7: [{1000,1,1,-1,-1}]
A8: 3 | B8: 每日挑战 | C8: 4 | D8: 2 | E8: 1 | F8: 6000 | H8: 6000 | I8: 4000 | J8: [{1000,1,1,-1,-1}]
A9: 4 | B9: 每日挑战 | C9: 5 | D9: 2 | E9: 5 | F9: 10000 | H9: 6000 | I9: 4000 | J9: [{1000,1,1,-1,-1}]
A10: 5 | B10: 每日挑战 | C10: 6 | D10: 3 | E10: 1 | F10: 14000 | H10: 7000 | I10: 6000 | J10: [{1000,1,1,-1,-1}]
A11: 6 | B11: 每日挑战 | C11: 7 | D11: 3 | E11: 7 | F11: 8000 | H11: 7000 | I11: 6000 | J11: [{1000,1,1,-1,-1}]
A12: 7 | B12: 每日挑战 | C12: 8 | D12: 4 | E12: 1 | F12: 10000 | H12: 8000 | I12: 8000 | J12: [{1000,1,1,-1,-1}]
A13: 8 | B13: 每日挑战 | C13: 9 | D13: 4 | E13: 2 | F13: 14000 | H13: 8000 | I13: 8000 | J13: [{1000,1,1,-1,-1}]
A14: 9 | B14: 每日挑战 | C14: 10 | D14: 4 | E14: 12 | F14: 1000 | H14: 8000 | I14: 8000 | J14: [{1000,1,1,-2,-1}]
A15: 10 | B15: 每日挑战 | C15: 11 | D15: 4 | E15: 16 | F15: 1000 | H15: 8000 | I15: 8000 | J15: [{1000,1,1,-2,-1}]
A16: 11 | B16: 每日挑战 | C16: 12 | D16: 5 | E16: 1 | F16: 18000 | H16: 10000 | I16: 10000 | J16: [{1000,1,1,-1,-1}]
A17: 12 | B17: 每日挑战 | C17: 13 | D17: 5 | E17: 9 | F17: 24000 | H17: 10000 | I17: 10000 | J17: [{1000,1,1,-1,-1}]
... A19: 14 | B19: 每日挑战 | C19: 15 | D19: 5 | E19: 26 | F19: 3000 | H19: 10000 | I19: 10000 | J19: [{1000,1,1,-2,-1}]
A20: 15 | B20: 每日挑战 | C20: 16 | D20: 5 | E20: 29 | G20: 1 | J20: []
A21: 16 | B21: 每日挑战 | C21: 17 | D21: 5 | E21: 30 | F21: 1000 | H21: 10000 | I21: 10000 | J21: [{1000,1,0,-4,-1}]
A22: 17 | B22: 每日挑战 | C22: 18 | D22: 6 | E22: 1 | F22: 9000 | H22: 12000 | I22: 12000 | J22: [{1000,1,1,-1,-1}]
A23: 18 | B23: 每日挑战 | C23: 19 | D23: 6 | E23: 6 | F23: 13000 | H23: 12000 | I23: 12000 | J23: [{1000,1,1,-1,-1}]
A24: 19 | B24: 每日挑战 | C24: 20 | D24: 6 | E24: 15 | F24: 4000 | H24: 12000 | I24: 12000 | J24: [{1000,1,1,-2,-1}]
A25: 20 | B25: 每日挑战 | C25: 21 | D25: 6 | E25: 15 | F25: 5000 | H25: 12000 | I25: 12000 | J25: [{1000,1,1,-2,-1}]
A26: 21 | B26: 每日挑战 | C26: 22 | D26: 7 | E26: 1 | F26: 17000 | H26: 15000 | I26: 14000 | J26: [{1000,1,1,-1,-1}]
A27: 22 | B27: 每日挑战 | C27: 23 | D27: 7 | E27: 8 | F27: 23000 | H27: 15000 | I27: 14000 | J27: [{1000,1,1,-1,-1}]
A28: 23 | B28: 每日挑战 | C28: 24 | D28: 7 | E28: 18 | F28: 6000 | H28: 15000 | I28: 14000 | J28: [{1000,1,1,-2,-1}]
A29: 24 | B29: 每日挑战 | C29: 25 | D29: 7 | E29: 25 | F29: 6000 | H29: 15000 | I29: 14000 | J29: [{1000,1,1,-2,-1}]
A30: 25 | B30: 每日挑战 | C30: 26 | D30: 7 | E30: 32 | F30: 1000 | H30: 15000 | I30: 14000 | J30: [{1000,1,1,-3,-1}]
A31: 26 | B31: 每日挑战 | C31: 27 | D31: 8 | E31: 1 | F31: 28000 | H31: 20000 | I31: 16000 | J31: [{1000,1,1,-1,-1}]
A32: 27 | B32: 每日挑战 | C32: 28 | D32: 8 | E32: 10 | F32: 6000 | H32: 20000 | I32: 16000 | J32: [{1000,1,1,-1,-1}]
... A48: 43 | B48: 每日挑战 | C48: 44 | D48: 10 | E48: 32 | F48: 8000 | H48: 50000 | I48: 20000 | J48: [{1000,1,1,-3,-1}]
A49: 44 | B49: 每日挑战 | C49: 45 | D49: 10 | E49: 40 | G49: 1 | J49: []
A50: 45 | B50: 每日挑战 | D50: 10 | E50: 41 | F50: 1000 | H50: 20000 | I50: 15000 | J50: [{1000,1,0,-5,-1}]

Sheet Sheet5
A1: =IF(E1="","",B1) -> 1 | B1: 1 | C1: 关卡14 | D1: [{1000 | E1: 1 | F1: 1 | G1: 1401 | H1: 101}] | I1: =_xlfn.TEXTJOIN(",",1,D1:H1) -> [{1000,1,1,1401,101}] | J1: 2 | K1: =IF(A1="","",IF(J1=1,VLOOKUP(A1,[1]怪物!$R$80:$V$99,4,0),VLOOKUP(A1,[1]怪物!$R$80:$V$99,2,0))*10000) -> 10000 | L1: =IF(A1="","",IF(K1=1,VLOOKUP(A1,[1]怪物!$R$80:$V$99,5,0),VLOOKUP(A1,[1]怪物!$R$80:$V$99,3,0))*10000) -> 10000 | M1: =IF(F1="","",IF(F1=0,10000,K1)) -> 10000 | N1: =IF(F1="","",IF(F1=0,10000,L1)) -> 10000
A2: =IF(E2="","",B2) -> 2 | B2: 2 | C2: 关卡14 | D2: [{1000 | E2: 1 | F2: 1 | G2: 1401 | H2: 101}] | I2: =_xlfn.TEXTJOIN(",",1,D2:H2) -> [{1000,1,1,1401,101}] | K2: =IF(A2="","",IF(J2=1,VLOOKUP(A2,[1]怪物!$R$80:$V$99,4,0),VLOOKUP(A2,[1]怪物!$R$80:$V$99,2,0))*10000) -> 10000 | L2: =IF(A2="","",IF(K2=1,VLOOKUP(A2,[1]怪物!$R$80:$V$99,5,0),VLOOKUP(A2,[1]怪物!$R$80:$V$99,3,0))*10000) -> 10000 | M2: =IF(F2="","",IF(F2=0,10000,K2)) -> 10000 | N2: =IF(F2="","",IF(F2=0,10000,L2)) -> 10000
A3: =IF(E3="","",B3) -> 3 | B3: 3 | C3: 关卡14 | D3: [{1000 | E3: 1 | F3: 1 | G3: 1401 | H3: 101}] | I3: =_xlfn.TEXTJOIN(",",1,D3:H3) -> [{1000,1,1,1401,101}] | K3: =IF(A3="","",IF(J3=1,VLOOKUP(A3,[1]怪物!$R$80:$V$99,4,0),VLOOKUP(A3,[1]怪物!$R$80:$V$99,2,0))*10000) -> 10000 | L3: =IF(A3="","",IF(K3=1,VLOOKUP(A3,[1]怪物!$R$80:$V$99,5,0),VLOOKUP(A3,[1]怪物!$R$80:$V$99,3,0))*10000) -> 10000 | M3: =IF(F3="","",IF(F3=0,10000,K3)) -> 10000 | N3: =IF(F3="","",IF(F3=0,10000,L3)) -> 10000
A4: =IF(E4="","",B4) -> 4 | B4: 4 | C4: 关卡14 | D4: [{1000 | E4: 1 | F4: 1 | G4: 1401 | H4: 101}] | I4: =_xlfn.TEXTJOIN(",",1,D4:H4) -> [{1000,1,1,1401,101}] | K4: =IF(A4="","",IF(J4=1,VLOOKUP(A4,[1]怪物!$R$80:$V$99,4,0),VLOOKUP(A4,[1]怪物!$R$80:$V$99,2,0))*10000) -> 10000 | L4: =IF(A4="","",IF(K4=1,VLOOKUP(A4,[1]怪物!$R$80:$V$99,5,0),VLOOKUP(A4,[1]怪物!$R$80:$V$99,3,0))*10000) -> 10000 | M4: =IF(F4="","",IF(F4=0,10000,K4)) -> 10000 | N4: =IF(F4="","",IF(F4=0,10000,L4)) -> 10000
A5: =IF(E5="","",B5) -> 5 | B5: 5 | C5: 关卡14 | D5: [{1000 | E5: 1 | F5: 1 | G5: 1401 | H5: 101}] | I5: =_xlfn.TEXTJOIN(",",1,D5:H5) -> [{1000,1,1,1401,101}] | K5: =IF(A5="","",IF(J5=1,VLOOKUP(A5,[1]怪物!$R$80:$V$99,4,0),VLOOKUP(A5,[1]怪物!$R$80:$V$99,2,0))*10000) -> 10000 | L5: =IF(A5="","",IF(K5=1,VLOOKUP(A5,[1]怪物!$R$80:$V$99,5,0),VLOOKUP(A5,[1]怪物!$R$80:$V$99,3,0))*10000) -> 10000 | M5: =IF(F5="","",IF(F5=0,10000,K5)) -> 10000 | N5: =IF(F5="","",IF(F5=0,10000,L5)) -> 10000
A6: =IF(E6="","",B6) -> 6 | B6: 6 | C6: 关卡14 | D6: [{1000 | E6: 1 | F6: 1 | G6: 1401 | H6: 101}] | I6: =_xlfn.TEXTJOIN(",",1,D6:H6) -> [{1000,1,1,1401,101}] | K6: =IF(A6="","",IF(J6=1,VLOOKUP(A6,[1]怪物!$R$80:$V$99,4,0),VLOOKUP(A6,[1]怪物!$R$80:$V$99,2,0))*10000) -> 15000 | L6: =IF(A6="","",IF(K6=1,VLOOKUP(A6,[1]怪物!$R$80:$V$99,5,0),VLOOKUP(A6,[1]怪物!$R$80:$V$99,3,0))*10000) -> 15000 | M6: =IF(F6="","",IF(F6=0,10000,K6)) -> 15000 | N6: =IF(F6="","",IF(F6=0,10000,L6)) -> 15000
A7: =IF(E7="","",B7) -> 7 | B7: 7 | C7: 关卡14 | D7: [{1000 | E7: 1 | F7: 1 | G7: 1401 | H7: 101}] | I7: =_xlfn.TEXTJOIN(",",1,D7:H7) -> [{1000,1,1,1401,101}] | K7: =IF(A7="","",IF(J7=1,VLOOKUP(A7,[1]怪物!$R$80:$V$99,4,0),VLOOKUP(A7,[1]怪物!$R$80:$V$99,2,0))*10000) -> 15000 | L7: =IF(A7="","",IF(K7=1,VLOOKUP(A7,[1]怪物!$R$80:$V$99,5,0),VLOOKUP(A7,[1]怪物!$R$80:$V$99,3,0))*10000) -> 15000 | M7: =IF(F7="","",IF(F7=0,10000,K7)) -> 15000 | N7: =IF(F7="","",IF(F7=0,10000,L7)) -> 15000
A8: =IF(E8="","",B8) -> 7 | B8: 7 | C8: 关卡14 | D8: [{1000 | E8: 1 | F8: 1 | G8: 1402 | H8: 101}] | I8: =_xlfn.TEXTJOIN(",",1,D8:H8) -> [{1000,1,1,1402,101}] | K8: =IF(A8="","",IF(J8=1,VLOOKUP(A8,[1]怪物!$R$80:$V$99,4,0),VLOOKUP(A8,[1]怪物!$R$80:$V$99,2,0))*10000) -> 15000 | L8: =IF(A8="","",IF(K8=1,VLOOKUP(A8,[1]怪物!$R$80:$V$99,5,0),VLOOKUP(A8,[1]怪物!$R$80:$V$99,3,0))*10000) -> 15000 | M8: =IF(F8="","",IF(F8=0,10000,K8)) -> 15000 | N8: =IF(F8="","",IF(F8=0,10000,L8)) -> 15000
A9: =IF(E9="","",B9) -> 8 | B9: 8 | C9: 关卡14 | D9: [{1000 | E9: 1 | F9: 1 | G9: 1401 | H9: 101}] | I9: =_xlfn.TEXTJOIN(",",1,D9:H9) -> [{1000,1,1,1401,101}] | K9: =IF(A9="","",IF(J9=1,VLOOKUP(A9,[1]怪物!$R$80:$V$99,4,0),VLOOKUP(A9,[1]怪物!$R$80:$V$99,2,0))*10000) -> 15000 | L9: =IF(A9="","",IF(K9=1,VLOOKUP(A9,[1]怪物!$R$80:$V$99,5,0),VLOOKUP(A9,[1]怪物!$R$80:$V$99,3,0))*10000) -> 15000 | M9: =IF(F9="","",IF(F9=0,10000,K9)) -> 15000 | N9: =IF(F9="","",IF(F9=0,10000,L9)) -> 15000
A10: =IF(E10="","",B10) -> 8 | B10: 8 | C10: 关卡14 | D10: [{1000 | E10: 1 | F10: 1 | G10: 1402 | H10: 101}] | I10: =_xlfn.TEXTJOIN(",",1,D10:H10) -> [{1000,1,1,1402,101}] | K10: =IF(A10="","",IF(J10=1,VLOOKUP(A10,[1]怪物!$R$80:$V$99,4,0),VLOOKUP(A10,[1]怪物!$R$80:$V$99,2,0))*10000) -> 15000 | L10: =IF(A10="","",IF(K10=1,VLOOKUP(A10,[1]怪物!$R$80:$V$99,5,0),VLOOKUP(A10,[1]怪物!$R$80:$V$99,3,0))*10000) -> 15000 | M10: =IF(F10="","",IF(F10=0,10000,K10)) -> 15000 | N10: =IF(F10="","",IF(F10=0,10000,L10)) -> 15000
A11: =IF(E11="","",B11) -> 9 | B11: 9 | C11: 关卡14 | D11: [{1000 | E11: 1 | F11: 1 | G11: 1401 | H11: 101}] | I11: =_xlfn.TEXTJOIN(",",1,D11:H11) -> [{1000,1,1,1401,101}] | K11: =IF(A11="","",IF(J11=1,VLOOKUP(A11,[1]怪物!$R$80:$V$99,4,0),VLOOKUP(A11,[1]怪物!$R$80:$V$99,2,0))*10000) -> #N/A | L11: =IF(A11="","",IF(K11=1,VLOOKUP(A11,[1]怪物!$R$80:$V$99,5,0),VLOOKUP(A11,[1]怪物!$R$80:$V$99,3,0))*10000) -> #N/A | M11: =IF(F11="","",IF(F11=0,10000,K11)) -> #N/A | N11: =IF(F11="","",IF(F11=0,10000,L11)) -> #N/A
A12: =IF(E12="","",B12) -> 9 | B12: 9 | C12: 关卡14 | D12: [{1000 | E12: 1 | F12: 1 | G12: 1402 | H12: 101}] | I12: =_xlfn.TEXTJOIN(",",1,D12:H12) -> [{1000,1,1,1402,101}] | K12: =IF(A12="","",IF(J12=1,VLOOKUP(A12,[1]怪物!$R$80:$V$99,4,0),VLOOKUP(A12,[1]怪物!$R$80:$V$99,2,0))*10000) -> #N/A | L12: =IF(A12="","",IF(K12=1,VLOOKUP(A12,[1]怪物!$R$80:$V$99,5,0),VLOOKUP(A12,[1]怪物!$R$80:$V$99,3,0))*10000) -> #N/A | M12: =IF(F12="","",IF(F12=0,10000,K12)) -> #N/A | N12: =IF(F12="","",IF(F12=0,10000,L12)) -> #N/A
A13: =IF(E13="","",B13) -> 10 | B13: 10 | C13: 关卡14 | D13: [{1000 | E13: 1 | F13: 1 | G13: 1401 | H13: 101}] | I13: =_xlfn.TEXTJOIN(",",1,D13:H13) -> [{1000,1,1,1401,101}] | K13: =IF(A13="","",IF(J13=1,VLOOKUP(A13,[1]怪物!$R$80:$V$99,4,0),VLOOKUP(A13,[1]怪物!$R$80:$V$99,2,0))*10000) -> #N/A | L13: =IF(A13="","",IF(K13=1,VLOOKUP(A13,[1]怪物!$R$80:$V$99,5,0),VLOOKUP(A13,[1]怪物!$R$80:$V$99,3,0))*10000) -> #N/A | M13: =IF(F13="","",IF(F13=0,10000,K13)) -> #N/A | N13: =IF(F13="","",IF(F13=0,10000,L13)) -> #N/A
A14: =IF(E14="","",B14) -> 10 | B14: 10 | C14: 关卡14 | D14: [{1000 | E14: 1 | F14: 1 | G14: 1402 | H14: 101}] | I14: =_xlfn.TEXTJOIN(",",1,D14:H14) -> [{1000,1,1,1402,101}] | K14: =IF(A14="","",IF(J14=1,VLOOKUP(A14,[1]怪物!$R$80:$V$99,4,0),VLOOKUP(A14,[1]怪物!$R$80:$V$99,2,0))*10000) -> #N/A | L14: =IF(A14="","",IF(K14=1,VLOOKUP(A14,[1]怪物!$R$80:$V$99,5,0),VLOOKUP(A14,[1]怪物!$R$80:$V$99,3,0))*10000) -> #N/A | M14: =IF(F14="","",IF(F14=0,10000,K14)) -> #N/A | N14: =IF(F14="","",IF(F14=0,10000,L14)) -> #N/A
A15: =IF(E15="","",B15) | B15: 10 | C15: 关卡14 | D15: [] | I15: =_xlfn.TEXTJOIN(",",1,D15:H15) -> [] | J15: 2 | K15: =IF(A15="","",IF(J15=1,VLOOKUP(A15,[1]怪物!$R$80:$V$99,4,0),VLOOKUP(A15,[1]怪物!$R$80:$V$99,2,0))*10000) | L15: =IF(A15="","",IF(K15=1,VLOOKUP(A15,[1]怪物!$R$80:$V$99,5,0),VLOOKUP(A15,[1]怪物!$R$80:$V$99,3,0))*10000) | M15: =IF(F15="","",IF(F15=0,10000,K15)) | N15: =IF(F15="","",IF(F15=0,10000,L15))
A16: =IF(E16="","",B16) -> 10 | B16: 10 | C16: 关卡14 | D16: [{1000 | E16: 1 | F16: 0 | G16: 1421 | H16: 41}] | I16: =_xlfn.TEXTJOIN(",",1,D16:H16) -> [{1000,1,0,1421,41}] | K16: =IF(A16="","",IF(J16=1,VLOOKUP(A16,[1]怪物!$R$80:$V$99,4,0),VLOOKUP(A16,[1]怪物!$R$80:$V$99,2,0))*10000) -> #N/A | L16: =IF(A16="","",IF(K16=1,VLOOKUP(A16,[1]怪物!$R$80:$V$99,5,0),VLOOKUP(A16,[1]怪物!$R$80:$V$99,3,0))*10000) -> #N/A | M16: =IF(F16="","",IF(F16=0,10000,K16)) -> 10000 | N16: =IF(F16="","",IF(F16=0,10000,L16)) -> 10000
A17: =IF(E17="","",B17) -> 11 | B17: 11 | C17: 关卡14 | D17: [{1000 | E17: 1 | F17: 1 | G17: 1401 | H17: 101}] | I17: =_xlfn.TEXTJOIN(",",1,D17:H17) -> [{1000,1,1,1401,101}] | K17: =IF(A17="","",IF(J17=1,VLOOKUP(A17,[1]怪物!$R$80:$V$99,4,0),VLOOKUP(A17,[1]怪物!$R$80:$V$99,2,0))*10000) -> #N/A | L17: =IF(A17="","",IF(K17=1,VLOOKUP(A17,[1]怪物!$R$80:$V$99,5,0),VLOOKUP(A17,[1]怪物!$R$80:$V$99,3,0))*10000) -> #N/A | M17: =IF(F17="","",IF(F17=0,10000,K17)) -> #N/A | N17: =IF(F17="","",IF(F17=0,10000,L17)) -> #N/A
A18: =IF(E18="","",B18) -> 11 | B18: 11 | C18: 关卡14 | D18: [{1000 | E18: 1 | F18: 1 | G18: 1402 | H18: 101}] | I18: =_xlfn.TEXTJOIN(",",1,D18:H18) -> [{1000,1,1,1402,101}] | K18: =IF(A18="","",IF(J18=1,VLOOKUP(A18,[1]怪物!$R$80:$V$99,4,0),VLOOKUP(A18,[1]怪物!$R$80:$V$99,2,0))*10000) -> #N/A | L18: =IF(A18="","",IF(K18=1,VLOOKUP(A18,[1]怪物!$R$80:$V$99,5,0),VLOOKUP(A18,[1]怪物!$R$80:$V$99,3,0))*10000) -> #N/A | M18: =IF(F18="","",IF(F18=0,10000,K18)) -> #N/A | N18: =IF(F18="","",IF(F18=0,10000,L18)) -> #N/A
A19: =IF(E19="","",B19) -> 12 | B19: 12 | C19: 关卡14 | D19: [{1000 | E19: 1 | F19: 1 | G19: 1401 | H19: 101}] | I19: =_xlfn.TEXTJOIN(",",1,D19:H19) -> [{1000,1,1,1401,101}] | K19: =IF(A19="","",IF(J19=1,VLOOKUP(A19,[1]怪物!$R$80:$V$99,4,0),VLOOKUP(A19,[1]怪物!$R$80:$V$99,2,0))*10000) -> #N/A | L19: =IF(A19="","",IF(K19=1,VLOOKUP(A19,[1]怪物!$R$80:$V$99,5,0),VLOOKUP(A19,[1]怪物!$R$80:$V$99,3,0))*10000) -> #N/A | M19: =IF(F19="","",IF(F19=0,10000,K19)) -> #N/A | N19: =IF(F19="","",IF(F19=0,10000,L19)) -> #N/A
A20: =IF(E20="","",B20) -> 12 | B20: 12 | C20: 关卡14 | D20: [{1000 | E20: 1 | F20: 1 | G20: 1402 | H20: 101}] | I20: =_xlfn.TEXTJOIN(",",1,D20:H20) -> [{1000,1,1,1402,101}] | K20: =IF(A20="","",IF(J20=1,VLOOKUP(A20,[1]怪物!$R$80:$V$99,4,0),VLOOKUP(A20,[1]怪物!$R$80:$V$99,2,0))*10000) -> #N/A | L20: =IF(A20="","",IF(K20=1,VLOOKUP(A20,[1]怪物!$R$80:$V$99,5,0),VLOOKUP(A20,[1]怪物!$R$80:$V$99,3,0))*10000) -> #N/A | M20: =IF(F20="","",IF(F20=0,10000,K20)) -> #N/A | N20: =IF(F20="","",IF(F20=0,10000,L20)) -> #N/A
A21: =IF(E21="","",B21) -> 13 | B21: 13 | C21: 关卡14 | D21: [{1000 | E21: 1 | F21: 1 | G21: 1401 | H21: 101}] | I21: =_xlfn.TEXTJOIN(",",1,D21:H21) -> [{1000,1,1,1401,101}] | K21: =IF(A21="","",IF(J21=1,VLOOKUP(A21,[1]怪物!$R$80:$V$99,4,0),VLOOKUP(A21,[1]怪物!$R$80:$V$99,2,0))*10000) -> #N/A | L21: =IF(A21="","",IF(K21=1,VLOOKUP(A21,[1]怪物!$R$80:$V$99,5,0),VLOOKUP(A21,[1]怪物!$R$80:$V$99,3,0))*10000) -> #N/A | M21: =IF(F21="","",IF(F21=0,10000,K21)) -> #N/A | N21: =IF(F21="","",IF(F21=0,10000,L21)) -> #N/A
A22: =IF(E22="","",B22) -> 13 | B22: 13 | C22: 关卡14 | D22: [{1000 | E22: 1 | F22: 1 | G22: 1402 | H22: 101}] | I22: =_xlfn.TEXTJOIN(",",1,D22:H22) -> [{1000,1,1,1402,101}] | K22: =IF(A22="","",IF(J22=1,VLOOKUP(A22,[1]怪物!$R$80:$V$99,4,0),VLOOKUP(A22,[1]怪物!$R$80:$V$99,2,0))*10000) -> #N/A | L22: =IF(A22="","",IF(K22=1,VLOOKUP(A22,[1]怪物!$R$80:$V$99,5,0),VLOOKUP(A22,[1]怪物!$R$80:$V$99,3,0))*10000) -> #N/A | M22: =IF(F22="","",IF(F22=0,10000,K22)) -> #N/A | N22: =IF(F22="","",IF(F22=0,10000,L22)) -> #N/A
A23: =IF(E23="","",B23) -> 14 | B23: 14 | C23: 关卡14 | D23: [{1000 | E23: 1 | F23: 1 | G23: 1401 | H23: 101}] | I23: =_xlfn.TEXTJOIN(",",1,D23:H23) -> [{1000,1,1,1401,101}] | K23: =IF(A23="","",IF(J23=1,VLOOKUP(A23,[1]怪物!$R$80:$V$99,4,0),VLOOKUP(A23,[1]怪物!$R$80:$V$99,2,0))*10000) -> #N/A | L23: =IF(A23="","",IF(K23=1,VLOOKUP(A23,[1]怪物!$R$80:$V$99,5,0),VLOOKUP(A23,[1]怪物!$R$80:$V$99,3,0))*10000) -> #N/A | M23: =IF(F23="","",IF(F23=0,10000,K23)) -> #N/A | N23: =IF(F23="","",IF(F23=0,10000,L23)) -> #N/A
A24: =IF(E24="","",B24) -> 14 | B24: 14 | C24: 关卡14 | D24: [{1000 | E24: 1 | F24: 1 | G24: 1402 | H24: 101}] | I24: =_xlfn.TEXTJOIN(",",1,D24:H24) -> [{1000,1,1,1402,101}] | K24: =IF(A24="","",IF(J24=1,VLOOKUP(A24,[1]怪物!$R$80:$V$99,4,0),VLOOKUP(A24,[1]怪物!$R$80:$V$99,2,0))*10000) -> #N/A | L24: =IF(A24="","",IF(K24=1,VLOOKUP(A24,[1]怪物!$R$80:$V$99,5,0),VLOOKUP(A24,[1]怪物!$R$80:$V$99,3,0))*10000) -> #N/A | M24: =IF(F24="","",IF(F24=0,10000,K24)) -> #N/A | N24: =IF(F24="","",IF(F24=0,10000,L24)) -> #N/A
A25: =IF(E25="","",B25) -> 14 | B25: 14 | C25: 关卡14 | D25: [{1000 | E25: 1 | F25: 1 | G25: 1403 | H25: 401}] | I25: =_xlfn.TEXTJOIN(",",1,D25:H25) -> [{1000,1,1,1403,401}] | J25: 1 | K25: =IF(A25="","",IF(J25=1,VLOOKUP(A25,[1]怪物!$R$80:$V$99,4,0),VLOOKUP(A25,[1]怪物!$R$80:$V$99,2,0))*10000) -> #N/A | L25: =IF(A25="","",IF(K25=1,VLOOKUP(A25,[1]怪物!$R$80:$V$99,5,0),VLOOKUP(A25,[1]怪物!$R$80:$V$99,3,0))*10000) -> #N/A | M25: =IF(F25="","",IF(F25=0,10000,K25)) -> #N/A | N25: =IF(F25="","",IF(F25=0,10000,L25)) -> #N/A
A26: =IF(E26="","",B26) -> 15 | B26: 15 | C26: 关卡14 | D26: [{1000 | E26: 1 | F26: 1 | G26: 1401 | H26: 101}] | I26: =_xlfn.TEXTJOIN(",",1,D26:H26) -> [{1000,1,1,1401,101}] | K26: =IF(A26="","",IF(J26=1,VLOOKUP(A26,[1]怪物!$R$80:$V$99,4,0),VLOOKUP(A26,[1]怪物!$R$80:$V$99,2,0))*10000) -> #N/A | L26: =IF(A26="","",IF(K26=1,VLOOKUP(A26,[1]怪物!$R$80:$V$99,5,0),VLOOKUP(A26,[1]怪物!$R$80:$V$99,3,0))*10000) -> #N/A | M26: =IF(F26="","",IF(F26=0,10000,K26)) -> #N/A | N26: =IF(F26="","",IF(F26=0,10000,L26)) -> #N/A
A27: =IF(E27="","",B27) -> 15 | B27: 15 | C27: 关卡14 | D27: [{1000 | E27: 1 | F27: 1 | G27: 1402 | H27: 101}] | I27: =_xlfn.TEXTJOIN(",",1,D27:H27) -> [{1000,1,1,1402,101}] | K27: =IF(A27="","",IF(J27=1,VLOOKUP(A27,[1]怪物!$R$80:$V$99,4,0),VLOOKUP(A27,[1]怪物!$R$80:$V$99,2,0))*10000) -> #N/A | L27: =IF(A27="","",IF(K27=1,VLOOKUP(A27,[1]怪物!$R$80:$V$99,5,0),VLOOKUP(A27,[1]怪物!$R$80:$V$99,3,0))*10000) -> #N/A | M27: =IF(F27="","",IF(F27=0,10000,K27)) -> #N/A | N27: =IF(F27="","",IF(F27=0,10000,L27)) -> #N/A
A28: =IF(E28="","",B28) -> 15 | B28: 15 | C28: 关卡14 | D28: [{1000 | E28: 1 | F28: 1 | G28: 1403 | H28: 401}] | I28: =_xlfn.TEXTJOIN(",",1,D28:H28) -> [{1000,1,1,1403,401}] | J28: 1 | K28: =IF(A28="","",IF(J28=1,VLOOKUP(A28,[1]怪物!$R$80:$V$99,4,0),VLOOKUP(A28,[1]怪物!$R$80:$V$99,2,0))*10000) -> #N/A | L28: =IF(A28="","",IF(K28=1,VLOOKUP(A28,[1]怪物!$R$80:$V$99,5,0),VLOOKUP(A28,[1]怪物!$R$80:$V$99,3,0))*10000) -> #N/A | M28: =IF(F28="","",IF(F28=0,10000,K28)) -> #N/A | N28: =IF(F28="","",IF(F28=0,10000,L28)) -> #N/A
A29: =IF(E29="","",B29) -> 16 | B29: 16 | C29: 关卡14 | D29: [{1000 | E29: 1 | F29: 1 | G29: 1401 | H29: 101}] | I29: =_xlfn.TEXTJOIN(",",1,D29:H29) -> [{1000,1,1,1401,101}] | K29: =IF(A29="","",IF(J29=1,VLOOKUP(A29,[1]怪物!$R$80:$V$99,4,0),VLOOKUP(A29,[1]怪物!$R$80:$V$99,2,0))*10000) -> #N/A | L29: =IF(A29="","",IF(K29=1,VLOOKUP(A29,[1]怪物!$R$80:$V$99,5,0),VLOOKUP(A29,[1]怪物!$R$80:$V$99,3,0))*10000) -> #N/A | M29: =IF(F29="","",IF(F29=0,10000,K29)) -> #N/A | N29: =IF(F29="","",IF(F29=0,10000,L29)) -> #N/A
A30: =IF(E30="","",B30) -> 16 | B30: 16 | C30: 关卡14 | D30: [{1000 | E30: 1 | F30: 1 | G30: 1402 | H30: 101}] | I30: =_xlfn.TEXTJOIN(",",1,D30:H30) -> [{1000,1,1,1402,101}] | K30: =IF(A30="","",IF(J30=1,VLOOKUP(A30,[1]怪物!$R$80:$V$99,4,0),VLOOKUP(A30,[1]怪物!$R$80:$V$99,2,0))*10000) -> #N/A | L30: =IF(A30="","",IF(K30=1,VLOOKUP(A30,[1]怪物!$R$80:$V$99,5,0),VLOOKUP(A30,[1]怪物!$R$80:$V$99,3,0))*10000) -> #N/A | M30: =IF(F30="","",IF(F30=0,10000,K30)) -> #N/A | N30: =IF(F30="","",IF(F30=0,10000,L30)) -> #N/A
A31: =IF(E31="","",B31) -> 16 | B31: 16 | C31: 关卡14 | D31: [{1000 | E31: 1 | F31: 1 | G31: 1403 | H31: 401}] | I31: =_xlfn.TEXTJOIN(",",1,D31:H31) -> [{1000,1,1,1403,401}] | J31: 1 | K31: =IF(A31="","",IF(J31=1,VLOOKUP(A31,[1]怪物!$R$80:$V$99,4,0),VLOOKUP(A31,[1]怪物!$R$80:$V$99,2,0))*10000) -> #N/A | L31: =IF(A31="","",IF(K31=1,VLOOKUP(A31,[1]怪物!$R$80:$V$99,5,0),VLOOKUP(A31,[1]怪物!$R$80:$V$99,3,0))*10000) -> #N/A | M31: =IF(F31="","",IF(F31=0,10000,K31)) -> #N/A | N31: =IF(F31="","",IF(F31=0,10000,L31)) -> #N/A
A32: =IF(E32="","",B32) -> 17 | B32: 17 | C32: 关卡14 | D32: [{1000 | E32: 1 | F32: 1 | G32: 1401 | H32: 101}] | I32: =_xlfn.TEXTJOIN(",",1,D32:H32) -> [{1000,1,1,1401,101}] | K32: =IF(A32="","",IF(J32=1,VLOOKUP(A32,[1]怪物!$R$80:$V$99,4,0),VLOOKUP(A32,[1]怪物!$R$80:$V$99,2,0))*10000) -> #N/A | L32: =IF(A32="","",IF(K32=1,VLOOKUP(A32,[1]怪物!$R$80:$V$99,5,0),VLOOKUP(A32,[1]怪物!$R$80:$V$99,3,0))*10000) -> #N/A | M32: =IF(F32="","",IF(F32=0,10000,K32)) -> #N/A | N32: =IF(F32="","",IF(F32=0,10000,L32)) -> #N/A
A33: =IF(E33="","",B33) -> 17 | B33: 17 | C33: 关卡14 | D33: [{1000 | E33: 1 | F33: 1 | G33: 1402 | H33: 101}] | I33: =_xlfn.TEXTJOIN(",",1,D33:H33) -> [{1000,1,1,1402,101}] | K33: =IF(A33="","",IF(J33=1,VLOOKUP(A33,[1]怪物!$R$80:$V$99,4,0),VLOOKUP(A33,[1]怪物!$R$80:$V$99,2,0))*10000) -> #N/A | L33: =IF(A33="","",IF(K33=1,VLOOKUP(A33,[1]怪物!$R$80:$V$99,5,0),VLOOKUP(A33,[1]怪物!$R$80:$V$99,3,0))*10000) -> #N/A | M33: =IF(F33="","",IF(F33=0,10000,K33)) -> #N/A | N33: =IF(F33="","",IF(F33=0,10000,L33)) -> #N/A
A34: =IF(E34="","",B34) -> 17 | B34: 17 | C34: 关卡14 | D34: [{1000 | E34: 1 | F34: 1 | G34: 1403 | H34: 401}] | I34: =_xlfn.TEXTJOIN(",",1,D34:H34) -> [{1000,1,1,1403,401}] | J34: 1 | K34: =IF(A34="","",IF(J34=1,VLOOKUP(A34,[1]怪物!$R$80:$V$99,4,0),VLOOKUP(A34,[1]怪物!$R$80:$V$99,2,0))*10000) -> #N/A | L34: =IF(A34="","",IF(K34=1,VLOOKUP(A34,[1]怪物!$R$80:$V$99,5,0),VLOOKUP(A34,[1]怪物!$R$80:$V$99,3,0))*10000) -> #N/A | M34: =IF(F34="","",IF(F34=0,10000,K34)) -> #N/A | N34: =IF(F34="","",IF(F34=0,10000,L34)) -> #N/A
A35: =IF(E35="","",B35) -> 18 | B35: 18 | C35: 关卡14 | D35: [{1000 | E35: 1 | F35: 1 | G35: 1401 | H35: 101}] | I35: =_xlfn.TEXTJOIN(",",1,D35:H35) -> [{1000,1,1,1401,101}] | K35: =IF(A35="","",IF(J35=1,VLOOKUP(A35,[1]怪物!$R$80:$V$99,4,0),VLOOKUP(A35,[1]怪物!$R$80:$V$99,2,0))*10000) -> #N/A | L35: =IF(A35="","",IF(K35=1,VLOOKUP(A35,[1]怪物!$R$80:$V$99,5,0),VLOOKUP(A35,[1]怪物!$R$80:$V$99,3,0))*10000) -> #N/A | M35: =IF(F35="","",IF(F35=0,10000,K35)) -> #N/A | N35: =IF(F35="","",IF(F35=0,10000,L35)) -> #N/A
A36: =IF(E36="","",B36) -> 18 | B36: 18 | C36: 关卡14 | D36: [{1000 | E36: 1 | F36: 1 | G36: 1402 | H36: 101}] | I36: =_xlfn.TEXTJOIN(",",1,D36:H36) -> [{1000,1,1,1402,101}] | K36: =IF(A36="","",IF(J36=1,VLOOKUP(A36,[1]怪物!$R$80:$V$99,4,0),VLOOKUP(A36,[1]怪物!$R$80:$V$99,2,0))*10000) -> #N/A | L36: =IF(A36="","",IF(K36=1,VLOOKUP(A36,[1]怪物!$R$80:$V$99,5,0),VLOOKUP(A36,[1]怪物!$R$80:$V$99,3,0))*10000) -> #N/A | M36: =IF(F36="","",IF(F36=0,10000,K36)) -> #N/A | N36: =IF(F36="","",IF(F36=0,10000,L36)) -> #N/A
A37: =IF(E37="","",B37) -> 18 | B37: 18 | C37: 关卡14 | D37: [{1000 | E37: 1 | F37: 1 | G37: 1403 | H37: 401}] | I37: =_xlfn.TEXTJOIN(",",1,D37:H37) -> [{1000,1,1,1403,401}] | J37: 1 | K37: =IF(A37="","",IF(J37=1,VLOOKUP(A37,[1]怪物!$R$80:$V$99,4,0),VLOOKUP(A37,[1]怪物!$R$80:$V$99,2,0))*10000) -> #N/A | L37: =IF(A37="","",IF(K37=1,VLOOKUP(A37,[1]怪物!$R$80:$V$99,5,0),VLOOKUP(A37,[1]怪物!$R$80:$V$99,3,0))*10000) -> #N/A | M37: =IF(F37="","",IF(F37=0,10000,K37)) -> #N/A | N37: =IF(F37="","",IF(F37=0,10000,L37)) -> #N/A
A38: =IF(E38="","",B38) -> 19 | B38: 19 | C38: 关卡14 | D38: [{1000 | E38: 1 | F38: 1 | G38: 1401 | H38: 101}] | I38: =_xlfn.TEXTJOIN(",",1,D38:H38) -> [{1000,1,1,1401,101}] | K38: =IF(A38="","",IF(J38=1,VLOOKUP(A38,[1]怪物!$R$80:$V$99,4,0),VLOOKUP(A38,[1]怪物!$R$80:$V$99,2,0))*10000) -> #N/A | L38: =IF(A38="","",IF(K38=1,VLOOKUP(A38,[1]怪物!$R$80:$V$99,5,0),VLOOKUP(A38,[1]怪物!$R$80:$V$99,3,0))*10000) -> #N/A | M38: =IF(F38="","",IF(F38=0,10000,K38)) -> #N/A | N38: =IF(F38="","",IF(F38=0,10000,L38)) -> #N/A
A39: =IF(E39="","",B39) -> 19 | B39: 19 | C39: 关卡14 | D39: [{1000 | E39: 1 | F39: 1 | G39: 1402 | H39: 101}] | I39: =_xlfn.TEXTJOIN(",",1,D39:H39) -> [{1000,1,1,1402,101}] | K39: =IF(A39="","",IF(J39=1,VLOOKUP(A39,[1]怪物!$R$80:$V$99,4,0),VLOOKUP(A39,[1]怪物!$R$80:$V$99,2,0))*10000) -> #N/A | L39: =IF(A39="","",IF(K39=1,VLOOKUP(A39,[1]怪物!$R$80:$V$99,5,0),VLOOKUP(A39,[1]怪物!$R$80:$V$99,3,0))*10000) -> #N/A | M39: =IF(F39="","",IF(F39=0,10000,K39)) -> #N/A | N39: =IF(F39="","",IF(F39=0,10000,L39)) -> #N/A
A40: =IF(E40="","",B40) -> 19 | B40: 19 | C40: 关卡14 | D40: [{1000 | E40: 1 | F40: 1 | G40: 1403 | H40: 401}] | I40: =_xlfn.TEXTJOIN(",",1,D40:H40) -> [{1000,1,1,1403,401}] | J40: 1 | K40: =IF(A40="","",IF(J40=1,VLOOKUP(A40,[1]怪物!$R$80:$V$99,4,0),VLOOKUP(A40,[1]怪物!$R$80:$V$99,2,0))*10000) -> #N/A | L40: =IF(A40="","",IF(K40=1,VLOOKUP(A40,[1]怪物!$R$80:$V$99,5,0),VLOOKUP(A40,[1]怪物!$R$80:$V$99,3,0))*10000) -> #N/A | M40: =IF(F40="","",IF(F40=0,10000,K40)) -> #N/A | N40: =IF(F40="","",IF(F40=0,10000,L40)) -> #N/A
...

Sheet Sheet6
B1: 1 | C1: 5201 | D1: =IF(COUNTIF(B1:B1,B1)>1,"",B1) -> 1 | E1: =IF(D1="","",C1) -> 5201 | F1: ="["&_xlfn.TEXTJOIN(",",1,E1:E38)&"]" -> [5201,5202,5203,5204,5205,5206,5207,5209,5211,5213,5217,5219,5221,5223,5225,5227,5229,5231,5233,5235]
B2: 2 | C2: 5202 | D2: =IF(COUNTIF(B1:B2,B2)>1,"",B2) -> 2 | E2: =IF(D2="","",C2) -> 5202
B3: 3 | C3: 5203 | D3: =IF(COUNTIF(B1:B3,B3)>1,"",B3) -> 3 | E3: =IF(D3="","",C3) -> 5203
B4: 4 | C4: 5204 | D4: =IF(COUNTIF(B1:B4,B4)>1,"",B4) -> 4 | E4: =IF(D4="","",C4) -> 5204
B5: 5 | C5: 5205 | D5: =IF(COUNTIF(B1:B5,B5)>1,"",B5) -> 5 | E5: =IF(D5="","",C5) -> 5205
B6: 6 | C6: 5206 | D6: =IF(COUNTIF(B1:B6,B6)>1,"",B6) -> 6 | E6: =IF(D6="","",C6) -> 5206
B7: 7 | C7: 5207 | D7: =IF(COUNTIF(B1:B7,B7)>1,"",B7) -> 7 | E7: =IF(D7="","",C7) -> 5207
B8: 7 | C8: 5208 | D8: =IF(COUNTIF(B1:B8,B8)>1,"",B8) | E8: =IF(D8="","",C8)
B9: 8 | C9: 5209 | D9: =IF(COUNTIF(B1:B9,B9)>1,"",B9) -> 8 | E9: =IF(D9="","",C9) -> 5209
B10: 8 | C10: 5210 | D10: =IF(COUNTIF(B1:B10,B10)>1,"",B10) | E10: =IF(D10="","",C10)
B11: 9 | C11: 5211 | D11: =IF(COUNTIF(B1:B11,B11)>1,"",B11) -> 9 | E11: =IF(D11="","",C11) -> 5211
B12: 9 | C12: 5212 | D12: =IF(COUNTIF(B1:B12,B12)>1,"",B12) | E12: =IF(D12="","",C12)
B13: 10 | C13: 5213 | D13: =IF(COUNTIF(B1:B13,B13)>1,"",B13) -> 10 | E13: =IF(D13="","",C13) -> 5213
B14: 10 | C14: 5214 | D14: =IF(COUNTIF(B1:B14,B14)>1,"",B14) | E14: =IF(D14="","",C14)
B15: 10 | C15: 5215 | D15: =IF(COUNTIF(B1:B15,B15)>1,"",B15) | E15: =IF(D15="","",C15)
B16: 10 | C16: 5216 | D16: =IF(COUNTIF(B1:B16,B16)>1,"",B16) | E16: =IF(D16="","",C16)
B17: 11 | C17: 5217 | D17: =IF(COUNTIF(B1:B17,B17)>1,"",B17) -> 11 | E17: =IF(D17="","",C17) -> 5217
B18: 11 | C18: 5218 | D18: =IF(COUNTIF(B1:B18,B18)>1,"",B18) | E18: =IF(D18="","",C18)
B19: 12 | C19: 5219 | D19: =IF(COUNTIF(B1:B19,B19)>1,"",B19) -> 12 | E19: =IF(D19="","",C19) -> 5219
B20: 12 | C20: 5220 | D20: =IF(COUNTIF(B1:B20,B20)>1,"",B20) | E20: =IF(D20="","",C20)
B21: 13 | C21: 5221 | D21: =IF(COUNTIF(B1:B21,B21)>1,"",B21) -> 13 | E21: =IF(D21="","",C21) -> 5221
B22: 13 | C22: 5222 | D22: =IF(COUNTIF(B1:B22,B22)>1,"",B22) | E22: =IF(D22="","",C22)
B23: 14 | C23: 5223 | D23: =IF(COUNTIF(B1:B23,B23)>1,"",B23) -> 14 | E23: =IF(D23="","",C23) -> 5223
B24: 14 | C24: 5224 | D24: =IF(COUNTIF(B1:B24,B24)>1,"",B24) | E24: =IF(D24="","",C24)
B25: 15 | C25: 5225 | D25: =IF(COUNTIF(B1:B25,B25)>1,"",B25) -> 15 | E25: =IF(D25="","",C25) -> 5225
B26: 15 | C26: 5226 | D26: =IF(COUNTIF(B1:B26,B26)>1,"",B26) | E26: =IF(D26="","",C26)
B27: 16 | C27: 5227 | D27: =IF(COUNTIF(B1:B27,B27)>1,"",B27) -> 16 | E27: =IF(D27="","",C27) -> 5227
B28: 16 | C28: 5228 | D28: =IF(COUNTIF(B1:B28,B28)>1,"",B28) | E28: =IF(D28="","",C28)
B29: 17 | C29: 5229 | D29: =IF(COUNTIF(B1:B29,B29)>1,"",B29) -> 17 | E29: =IF(D29="","",C29) -> 5229
B30: 17 | C30: 5230 | D30: =IF(COUNTIF(B1:B30,B30)>1,"",B30) | E30: =IF(D30="","",C30)
B31: 18 | C31: 5231 | D31: =IF(COUNTIF(B1:B31,B31)>1,"",B31) -> 18 | E31: =IF(D31="","",C31) -> 5231
B32: 18 | C32: 5232 | D32: =IF(COUNTIF(B1:B32,B32)>1,"",B32) | E32: =IF(D32="","",C32)
B33: 19 | C33: 5233 | D33: =IF(COUNTIF(B1:B33,B33)>1,"",B33) -> 19 | E33: =IF(D33="","",C33) -> 5233
B34: 19 | C34: 5234 | D34: =IF(COUNTIF(B1:B34,B34)>1,"",B34) | E34: =IF(D34="","",C34)
B35: 20 | C35: 5235 | D35: =IF(COUNTIF(B1:B35,B35)>1,"",B35) -> 20 | E35: =IF(D35="","",C35) -> 5235
B36: 20 | C36: 5236 | D36: =IF(COUNTIF(B1:B36,B36)>1,"",B36) | E36: =IF(D36="","",C36)
B37: 20 | C37: 5237 | D37: =IF(COUNTIF(B1:B37,B37)>1,"",B37) | E37: =IF(D37="","",C37)
B38: 20 | C38: 5238 | D38: =IF(COUNTIF(B1:B38,B38)>1,"",B38) | E38: =IF(D38="","",C38)
F39: 1 | G39: 5401 | H39: =IF(COUNTIF(F39:F39,F39)>1,"",F39) -> 1 | I39: =IF(H39="","",G39) -> 5401 | J39: ="["&_xlfn.TEXTJOIN(",",1,I39:I80)&"]" -> [5401,5402,5403,5404,5405,5406,5407,5409,5411,5413,5417,5419,5421,5423,5426,5429,5432,5435,5438,5441]
F40: 2 | G40: 5402 | H40: =IF(COUNTIF(F39:F40,F40)>1,"",F40) -> 2 | I40: =IF(H40="","",G40) -> 5402
...

Sheet Sheet4
G1: 时间 | H1: 数量 | I1: 重复出现 | J1: 怪物id | K1: 怪物id | L1: 出现方式 | M1: 时间 | N1: 数量 | O1: 重复出现 | P1: 怪物id | Q1: 出现方式 | R1: 出现方式 | S1: 时间 | T1: 数量 | U1: 重复出现 | V1: 怪物id | W1: 出现方式 | X1: 出现方式 | Y1: 时间 | Z1: 数量 | AA1: 重复出现 | AB1: 怪物id | AC1: 出现方式 | AD1: 出现方式 | AE1: 时间 | AF1: 数量 | AG1: 重复出现 | AH1: 怪物id | AI1: 出现方式 | AJ1: 出现方式 | AK1: 时间 | AL1: 数量 | AM1: 重复出现 | AN1: 怪物id | AO1: 出现方式 | AQ1: { | AR1: }
B2: 1011 | C2: 关卡1 | D2: =RIGHT(C2,1) -> 1 | F2: 1 | G2: 5000 | H2: 1 | I2: 1 | J2: 1 | K2: 1 | L2: 101 | M2: 5000 | N2: =H2 -> 1 | O2: 1 | P2: 1 | Q2: 55 | R2: 102 | S2: 5000 | T2: =N2 -> 1 | U2: 1 | V2: 1 | W2: 60 | X2: 103 | Y2: 5000 | Z2: =T2 -> 1 | AA2: 1 | AB2: 1 | AC2: 71 | AD2: 113 | AE2: 5000 | AF2: =Z2 -> 1 | AG2: 1 | AH2: 1 | AI2: 76 | AJ2: 111 | AP2: =IF(G2="","",$AQ$1&_xlfn.TEXTJOIN(",",1,G2:I2,K2,L2)&$AR$1) -> {5000,1,1,1,101} | AQ2: =IF(G2="","",$AQ$1&_xlfn.TEXTJOIN(",",1,M2:P2,R2)&$AR$1) -> {5000,1,1,1,102} | AR2: =IF(G2="","",$AQ$1&_xlfn.TEXTJOIN(",",1,S2:V2,X2)&$AR$1) -> {5000,1,1,1,103} | AS2: =IF(G2="","",$AQ$1&_xlfn.TEXTJOIN(",",1,Y2:AB2,AD2)&$AR$1) -> {5000,1,1,1,113} | AT2: =IF(G2="","",$AQ$1&_xlfn.TEXTJOIN(",",1,AE2:AH2,AJ2)&$AR$1) -> {5000,1,1,1,111} | AU2: =IF(AK2="","",IF(G2="","",$AQ$1&_xlfn.TEXTJOIN(",",1,AK2:AO2)&$AR$1)) | AV2: 1011 | AW2: =IF(AU2="","["&_xlfn.TEXTJOIN(",",1,AP2:AT2)&"]","["&_xlfn.TEXTJOIN(",",1,AP2:AU2)&"]") -> [{5000,1,1,1,101},{5000,1,1,1,102},{5000,1,1,1,103},{5000,1,1,1,113},{5000,1,1,1,111}]
B3: 1012 | C3: 关卡1 | D3: =RIGHT(C3,1) -> 1 | F3: 16 | G3: 5000 | H3: 1 | I3: 1 | J3: 1 | K3: 1 | L3: 101 | M3: 5000 | N3: =H3 -> 1 | O3: 1 | P3: 1 | Q3: 55 | R3: 103 | S3: 5000 | T3: =N3 -> 1 | U3: 1 | V3: 1 | W3: 75 | X3: 111 | Y3: 5000 | Z3: =T3 -> 1 | AA3: 1 | AB3: 1 | AC3: 73 | AD3: 112 | AE3: 5000 | AF3: =Z3 -> 1 | AG3: 1 | AH3: 1 | AI3: 78 | AJ3: 113 | AP3: =IF(G3="","",$AQ$1&_xlfn.TEXTJOIN(",",1,G3:I3,K3,L3)&$AR$1) -> {5000,1,1,1,101} | AQ3: =IF(G3="","",$AQ$1&_xlfn.TEXTJOIN(",",1,M3:P3,R3)&$AR$1) -> {5000,1,1,1,103} | AR3: =IF(G3="","",$AQ$1&_xlfn.TEXTJOIN(",",1,S3:V3,X3)&$AR$1) -> {5000,1,1,1,111} | AS3: =IF(G3="","",$AQ$1&_xlfn.TEXTJOIN(",",1,Y3:AB3,AD3)&$AR$1) -> {5000,1,1,1,112} | AT3: =IF(G3="","",$AQ$1&_xlfn.TEXTJOIN(",",1,AE3:AH3,AJ3)&$AR$1) -> {5000,1,1,1,113} | AU3: =IF(AK3="","",IF(G3="","",$AQ$1&_xlfn.TEXTJOIN(",",1,AK3:AO3)&$AR$1)) | AV3: 1012 | AW3: =IF(AU3="","["&_xlfn.TEXTJOIN(",",1,AP3:AT3)&"]","["&_xlfn.TEXTJOIN(",",1,AP3:AU3)&"]") -> [{5000,1,1,1,101},{5000,1,1,1,103},{5000,1,1,1,111},{5000,1,1,1,112},{5000,1,1,1,113}]
B4: 1013 | C4: 关卡1 | D4: =RIGHT(C4,1) -> 1 | F4: 31 | G4: 5000 | H4: 2 | I4: 1 | J4: 1 | K4: 1 | L4: =L2 -> 101 | M4: 5000 | N4: =H4 -> 2 | O4: 1 | P4: 1 | Q4: 55 | R4: =R2 -> 102 | S4: 5000 | T4: =N4 -> 2 | U4: 1 | V4: 1 | W4: 58 | X4: =X2 -> 103 | Y4: 5000 | Z4: =T4 -> 2 | AA4: 1 | AB4: 1 | AC4: 76 | AD4: =AD2 -> 113 | AE4: 5000 | AF4: =Z4 -> 2 | AG4: 1 | AH4: 1 | AI4: 79 | AJ4: =AJ2 -> 111 | AP4: =IF(G4="","",$AQ$1&_xlfn.TEXTJOIN(",",1,G4:I4,K4,L4)&$AR$1) -> {5000,2,1,1,101} | AQ4: =IF(G4="","",$AQ$1&_xlfn.TEXTJOIN(",",1,M4:P4,R4)&$AR$1) -> {5000,2,1,1,102} | AR4: =IF(G4="","",$AQ$1&_xlfn.TEXTJOIN(",",1,S4:V4,X4)&$AR$1) -> {5000,2,1,1,103} | AS4: =IF(G4="","",$AQ$1&_xlfn.TEXTJOIN(",",1,Y4:AB4,AD4)&$AR$1) -> {5000,2,1,1,113} | AT4: =IF(G4="","",$AQ$1&_xlfn.TEXTJOIN(",",1,AE4:AH4,AJ4)&$AR$1) -> {5000,2,1,1,111} | AU4: =IF(AK4="","",IF(G4="","",$AQ$1&_xlfn.TEXTJOIN(",",1,AK4:AO4)&$AR$1)) | AV4: 1013 | AW4: =IF(AU4="","["&_xlfn.TEXTJOIN(",",1,AP4:AT4)&"]","["&_xlfn.TEXTJOIN(",",1,AP4:AU4)&"]") -> [{5000,2,1,1,101},{5000,2,1,1,102},{5000,2,1,1,103},{5000,2,1,1,113},{5000,2,1,1,111}]
B5: 1014 | C5: 关卡1 | D5: =RIGHT(C5,1) -> 1 | F5: 46 | G5: 5000 | H5: 2 | I5: 1 | J5: 1 | K5: 1 | L5: =L3 -> 101 | M5: 5000 | N5: =H5 -> 2 | O5: 1 | P5: 1 | Q5: 55 | R5: =R3 -> 103 | S5: 5000 | T5: =N5 -> 2 | U5: 1 | V5: 2 | W5: 76 | X5: =X3 -> 111 | Y5: 5000 | Z5: =T5 -> 2 | AA5: 1 | AB5: 1 | AC5: 71 | AD5: =AD3 -> 112 | AE5: 5000 | AF5: =Z5 -> 2 | AG5: 1 | AH5: 1 | AI5: 71 | AJ5: =AJ3 -> 113 | AP5: =IF(G5="","",$AQ$1&_xlfn.TEXTJOIN(",",1,G5:I5,K5,L5)&$AR$1) -> {5000,2,1,1,101} | AQ5: =IF(G5="","",$AQ$1&_xlfn.TEXTJOIN(",",1,M5:P5,R5)&$AR$1) -> {5000,2,1,1,103} | AR5: =IF(G5="","",$AQ$1&_xlfn.TEXTJOIN(",",1,S5:V5,X5)&$AR$1) -> {5000,2,1,2,111} | AS5: =IF(G5="","",$AQ$1&_xlfn.TEXTJOIN(",",1,Y5:AB5,AD5)&$AR$1) -> {5000,2,1,1,112} | AT5: =IF(G5="","",$AQ$1&_xlfn.TEXTJOIN(",",1,AE5:AH5,AJ5)&$AR$1) -> {5000,2,1,1,113} | AU5: =IF(AK5="","",IF(G5="","",$AQ$1&_xlfn.TEXTJOIN(",",1,AK5:AO5)&$AR$1)) | AV5: 1014 | AW5: =IF(AU5="","["&_xlfn.TEXTJOIN(",",1,AP5:AT5)&"]","["&_xlfn.TEXTJOIN(",",1,AP5:AU5)&"]") -> [{5000,2,1,1,101},{5000,2,1,1,103},{5000,2,1,2,111},{5000,2,1,1,112},{5000,2,1,1,113}]
B6: 1015 | C6: 关卡1 | D6: =RIGHT(C6,1) -> 1 | F6: 61 | G6: 5000 | H6: 2 | I6: 1 | J6: 3 | K6: 3 | L6: =L4 -> 101 | M6: 5000 | N6: =H6 -> 2 | O6: 1 | P6: 3 | Q6: 56 | R6: =R4 -> 102 | S6: 5000 | T6: =N6 -> 2 | U6: 1 | V6: 3 | W6: 57 | X6: =X4 -> 103 | Y6: 5000 | Z6: =T6 -> 2 | AA6: 1 | AB6: 3 | AC6: 72 | AD6: =AD4 -> 113 | AE6: 5000 | AF6: =Z6 -> 2 | AG6: 1 | AH6: 3 | AI6: 71 | AJ6: =AJ4 -> 111 | AP6: =IF(G6="","",$AQ$1&_xlfn.TEXTJOIN(",",1,G6:I6,K6,L6)&$AR$1) -> {5000,2,1,3,101} | AQ6: =IF(G6="","",$AQ$1&_xlfn.TEXTJOIN(",",1,M6:P6,R6)&$AR$1) -> {5000,2,1,3,102} | AR6: =IF(G6="","",$AQ$1&_xlfn.TEXTJOIN(",",1,S6:V6,X6)&$AR$1) -> {5000,2,1,3,103} | AS6: =IF(G6="","",$AQ$1&_xlfn.TEXTJOIN(",",1,Y6:AB6,AD6)&$AR$1) -> {5000,2,1,3,113} | AT6: =IF(G6="","",$AQ$1&_xlfn.TEXTJOIN(",",1,AE6:AH6,AJ6)&$AR$1) -> {5000,2,1,3,111} | AU6: =IF(AK6="","",IF(G6="","",$AQ$1&_xlfn.TEXTJOIN(",",1,AK6:AO6)&$AR$1)) | AV6: 1015 | AW6: =IF(AU6="","["&_xlfn.TEXTJOIN(",",1,AP6:AT6)&"]","["&_xlfn.TEXTJOIN(",",1,AP6:AU6)&"]") -> [{5000,2,1,3,101},{5000,2,1,3,102},{5000,2,1,3,103},{5000,2,1,3,113},{5000,2,1,3,111}]
B7: 1016 | C7: 关卡1 | D7: =RIGHT(C7,1) -> 1 | F7: 76 | G7: 5000 | H7: 2 | I7: 1 | J7: 1 | K7: 1 | L7: =L5 -> 101 | M7: 5000 | N7: =H7 -> 2 | O7: 1 | P7: 1 | Q7: 59 | R7: =R5 -> 103 | S7: 5000 | T7: =N7 -> 2 | U7: 1 | V7: 2 | W7: 71 | X7: =X5 -> 111 | Y7: 5000 | Z7: =T7 -> 2 | AA7: 1 | AB7: 1 | AC7: 71 | AD7: =AD5 -> 112 | AE7: 5000 | AF7: =Z7 -> 2 | AG7: 1 | AH7: 1 | AI7: 79 | AJ7: =AJ5 -> 113 | AP7: =IF(G7="","",$AQ$1&_xlfn.TEXTJOIN(",",1,G7:I7,K7,L7)&$AR$1) -> {5000,2,1,1,101} | AQ7: =IF(G7="","",$AQ$1&_xlfn.TEXTJOIN(",",1,M7:P7,R7)&$AR$1) -> {5000,2,1,1,103} | AR7: =IF(G7="","",$AQ$1&_xlfn.TEXTJOIN(",",1,S7:V7,X7)&$AR$1) -> {5000,2,1,2,111} | AS7: =IF(G7="","",$AQ$1&_xlfn.TEXTJOIN(",",1,Y7:AB7,AD7)&$AR$1) -> {5000,2,1,1,112} | AT7: =IF(G7="","",$AQ$1&_xlfn.TEXTJOIN(",",1,AE7:AH7,AJ7)&$AR$1) -> {5000,2,1,1,113} | AU7: =IF(AK7="","",IF(G7="","",$AQ$1&_xlfn.TEXTJOIN(",",1,AK7:AO7)&$AR$1)) | AV7: 1016 | AW7: =IF(AU7="","["&_xlfn.TEXTJOIN(",",1,AP7:AT7)&"]","["&_xlfn.TEXTJOIN(",",1,AP7:AU7)&"]") -> [{5000,2,1,1,101},{5000,2,1,1,103},{5000,2,1,2,111},{5000,2,1,1,112},{5000,2,1,1,113}]
B8: 1017 | C8: 关卡1 | D8: =RIGHT(C8,1) -> 1 | F8: 91 | G8: 5000 | H8: 2 | I8: 1 | J8: 1 | K8: 1 | L8: =L6 -> 101 | M8: 5000 | N8: =H8 -> 2 | O8: 1 | P8: 1 | Q8: 54 | R8: =R6 -> 102 | S8: 5000 | T8: =N8 -> 2 | U8: 1 | V8: 2 | W8: 51 | X8: =X6 -> 103 | Y8: 5000 | Z8: =T8 -> 2 | AA8: 1 | AB8: 1 | AC8: 71 | AD8: =AD6 -> 113 | AE8: 5000 | AF8: =Z8 -> 2 | AG8: 1 | AH8: 2 | AI8: 77 | AJ8: =AJ6 -> 111 | AP8: =IF(G8="","",$AQ$1&_xlfn.TEXTJOIN(",",1,G8:I8,K8,L8)&$AR$1) -> {5000,2,1,1,101} | AQ8: =IF(G8="","",$AQ$1&_xlfn.TEXTJOIN(",",1,M8:P8,R8)&$AR$1) -> {5000,2,1,1,102} | AR8: =IF(G8="","",$AQ$1&_xlfn.TEXTJOIN(",",1,S8:V8,X8)&$AR$1) -> {5000,2,1,2,103} | AS8: =IF(G8="","",$AQ$1&_xlfn.TEXTJOIN(",",1,Y8:AB8,AD8)&$AR$1) -> {5000,2,1,1,113} | AT8: =IF(G8="","",$AQ$1&_xlfn.TEXTJOIN(",",1,AE8:AH8,AJ8)&$AR$1) -> {5000,2,1,2,111} | AU8: =IF(AK8="","",IF(G8="","",$AQ$1&_xlfn.TEXTJOIN(",",1,AK8:AO8)&$AR$1)) | AV8: 1017 | AW8: =IF(AU8="","["&_xlfn.TEXTJOIN(",",1,AP8:AT8)&"]","["&_xlfn.TEXTJOIN(",",1,AP8:AU8)&"]") -> [{5000,2,1,1,101},{5000,2,1,1,102},{5000,2,1,2,103},{5000,2,1,1,113},{5000,2,1,2,111}]
B9: 1018 | C9: 关卡1 | D9: =RIGHT(C9,1) -> 1 | F9: 106 | G9: 5000 | H9: 2 | I9: 1 | J9: 1 | K9: 1 | L9: =L7 -> 101 | M9: 5000 | N9: =H9 -> 2 | O9: 1 | P9: 1 | Q9: 55 | R9: =R7 -> 103 | S9: 5000 | T9: =N9 -> 2 | U9: 1 | V9: 2 | W9: 73 | X9: =X7 -> 111 | Y9: 5000 | Z9: =T9 -> 2 | AA9: 1 | AB9: 1 | AC9: 78 | AD9: =AD7 -> 112 | AE9: 5000 | AF9: =Z9 -> 2 | AG9: 1 | AH9: 2 | AI9: 71 | AJ9: =AJ7 -> 113 | AP9: =IF(G9="","",$AQ$1&_xlfn.TEXTJOIN(",",1,G9:I9,K9,L9)&$AR$1) -> {5000,2,1,1,101} | AQ9: =IF(G9="","",$AQ$1&_xlfn.TEXTJOIN(",",1,M9:P9,R9)&$AR$1) -> {5000,2,1,1,103} | AR9: =IF(G9="","",$AQ$1&_xlfn.TEXTJOIN(",",1,S9:V9,X9)&$AR$1) -> {5000,2,1,2,111} | AS9: =IF(G9="","",$AQ$1&_xlfn.TEXTJOIN(",",1,Y9:AB9,AD9)&$AR$1) -> {5000,2,1,1,112} | AT9: =IF(G9="","",$AQ$1&_xlfn.TEXTJOIN(",",1,AE9:AH9,AJ9)&$AR$1) -> {5000,2,1,2,113} | AU9: =IF(AK9="","",IF(G9="","",$AQ$1&_xlfn.TEXTJOIN(",",1,AK9:AO9)&$AR$1)) | AV9: 1018 | AW9: =IF(AU9="","["&_xlfn.TEXTJOIN(",",1,AP9:AT9)&"]","["&_xlfn.TEXTJOIN(",",1,AP9:AU9)&"]") -> [{5000,2,1,1,101},{5000,2,1,1,103},{5000,2,1,2,111},{5000,2,1,1,112},{5000,2,1,2,113}]
B10: 1019 | C10: 关卡1 | D10: =RIGHT(C10,1) -> 1 | F10: 121 | G10: 5000 | H10: 3 | I10: 1 | J10: 3 | K10: 3 | L10: =L8 -> 101 | M10: 5000 | N10: =H10 -> 3 | O10: 1 | P10: 3 | Q10: 54 | R10: =R8 -> 102 | S10: 5000 | T10: =N10 -> 3 | U10: 1 | V10: 3 | W10: 51 | X10: =X8 -> 103 | Y10: 5000 | Z10: =T10 -> 3 | AA10: 1 | AB10: 3 | AC10: 71 | AD10: =AD8 -> 113 | AE10: 5000 | AF10: =Z10 -> 3 | AG10: 1 | AH10: 3 | AI10: 79 | AJ10: =AJ8 -> 111 | AP10: =IF(G10="","",$AQ$1&_xlfn.TEXTJOIN(",",1,G10:I10,K10,L10)&$AR$1) -> {5000,3,1,3,101} | AQ10: =IF(G10="","",$AQ$1&_xlfn.TEXTJOIN(",",1,M10:P10,R10)&$AR$1) -> {5000,3,1,3,102} | AR10: =IF(G10="","",$AQ$1&_xlfn.TEXTJOIN(",",1,S10:V10,X10)&$AR$1) -> {5000,3,1,3,103} | AS10: =IF(G10="","",$AQ$1&_xlfn.TEXTJOIN(",",1,Y10:AB10,AD10)&$AR$1) -> {5000,3,1,3,113} | AT10: =IF(G10="","",$AQ$1&_xlfn.TEXTJOIN(",",1,AE10:AH10,AJ10)&$AR$1) -> {5000,3,1,3,111} | AU10: =IF(AK10="","",IF(G10="","",$AQ$1&_xlfn.TEXTJOIN(",",1,AK10:AO10)&$AR$1)) | AV10: 1019 | AW10: =IF(AU10="","["&_xlfn.TEXTJOIN(",",1,AP10:AT10)&"]","["&_xlfn.TEXTJOIN(",",1,AP10:AU10)&"]") -> [{5000,3,1,3,101},{5000,3,1,3,102},{5000,3,1,3,103},{5000,3,1,3,113},{5000,3,1,3,111}]
B11: 1020 | C11: 关卡1 | D11: =RIGHT(C11,1) -> 1 | F11: 136 | G11: 5000 | H11: 3 | I11: 1 | J11: 1 | K11: 1 | L11: =L9 -> 101 | M11: 5000 | N11: =H11 -> 3 | O11: 1 | P11: 1 | Q11: 54 | R11: =R9 -> 103 | S11: 5000 | T11: =N11 -> 3 | U11: 1 | V11: 2 | W11: 76 | X11: =X9 -> 111 | Y11: 5000 | Z11: =T11 -> 3 | AA11: 1 | AB11: 1 | AC11: 72 | AD11: =AD9 -> 112 | AE11: 5000 | AF11: =Z11 -> 3 | AG11: 1 | AH11: 2 | AI11: 74 | AJ11: =AJ9 -> 113 | AP11: =IF(G11="","",$AQ$1&_xlfn.TEXTJOIN(",",1,G11:I11,K11,L11)&$AR$1) -> {5000,3,1,1,101} | AQ11: =IF(G11="","",$AQ$1&_xlfn.TEXTJOIN(",",1,M11:P11,R11)&$AR$1) -> {5000,3,1,1,103} | AR11: =IF(G11="","",$AQ$1&_xlfn.TEXTJOIN(",",1,S11:V11,X11)&$AR$1) -> {5000,3,1,2,111} | AS11: =IF(G11="","",$AQ$1&_xlfn.TEXTJOIN(",",1,Y11:AB11,AD11)&$AR$1) -> {5000,3,1,1,112} | AT11: =IF(G11="","",$AQ$1&_xlfn.TEXTJOIN(",",1,AE11:AH11,AJ11)&$AR$1) -> {5000,3,1,2,113} | AU11: =IF(AK11="","",IF(G11="","",$AQ$1&_xlfn.TEXTJOIN(",",1,AK11:AO11)&$AR$1)) | AV11: 1020 | AW11: =IF(AU11="","["&_xlfn.TEXTJOIN(",",1,AP11:AT11)&"]","["&_xlfn.TEXTJOIN(",",1,AP11:AU11)&"]") -> [{5000,3,1,1,101},{5000,3,1,1,103},{5000,3,1,2,111},{5000,3,1,1,112},{5000,3,1,2,113}]
B12: 1021 | C12: 关卡1 | D12: =RIGHT(C12,1) -> 1 | F12: 151 | G12: 5000 | H12: 3 | I12: 1 | J12: 1 | K12: 1 | L12: =L10 -> 101 | M12: 5000 | N12: =H12 -> 3 | O12: 1 | P12: 1 | Q12: 54 | R12: =R10 -> 102 | S12: 5000 | T12: =N12 -> 3 | U12: 1 | V12: 2 | W12: 56 | X12: =X10 -> 103 | Y12: 5000 | Z12: =T12 -> 3 | AA12: 1 | AB12: 1 | AC12: 72 | AD12: =AD10 -> 113 | AE12: 5000 | AF12: =Z12 -> 3 | AG12: 1 | AH12: 2 | AI12: 74 | AJ12: =AJ10 -> 111 | AP12: =IF(G12="","",$AQ$1&_xlfn.TEXTJOIN(",",1,G12:I12,K12,L12)&$AR$1) -> {5000,3,1,1,101} | AQ12: =IF(G12="","",$AQ$1&_xlfn.TEXTJOIN(",",1,M12:P12,R12)&$AR$1) -> {5000,3,1,1,102} | AR12: =IF(G12="","",$AQ$1&_xlfn.TEXTJOIN(",",1,S12:V12,X12)&$AR$1) -> {5000,3,1,2,103} | AS12: =IF(G12="","",$AQ$1&_xlfn.TEXTJOIN(",",1,Y12:AB12,AD12)&$AR$1) -> {5000,3,1,1,113} | AT12: =IF(G12="","",$AQ$1&_xlfn.TEXTJOIN(",",1,AE12:AH12,AJ12)&$AR$1) -> {5000,3,1,2,111} | AU12: =IF(AK12="","",IF(G12="","",$AQ$1&_xlfn.TEXTJOIN(",",1,AK12:AO12)&$AR$1)) | AV12: 1021 | AW12: =IF(AU12="","["&_xlfn.TEXTJOIN(",",1,AP12:AT12)&"]","["&_xlfn.TEXTJOIN(",",1,AP12:AU12)&"]") -> [{5000,3,1,1,101},{5000,3,1,1,102},{5000,3,1,2,103},{5000,3,1,1,113},{5000,3,1,2,111}]
B13: 1022 | C13: 关卡1 | D13: =RIGHT(C13,1) -> 1 | F13: 166 | G13: 5000 | H13: 3 | I13: 1 | J13: 1 | K13: 1 | L13: =L11 -> 101 | M13: 5000 | N13: =H13 -> 3 | O13: 1 | P13: 1 | Q13: 59 | R13: =R11 -> 103 | S13: 5000 | T13: =N13 -> 3 | U13: 1 | V13: 2 | W13: 79 | X13: =X11 -> 111 | Y13: 5000 | Z13: =T13 -> 3 | AA13: 1 | AB13: 1 | AC13: 71 | AD13: =AD11 -> 112 | AE13: 5000 | AF13: =Z13 -> 3 | AG13: 1 | AH13: 2 | AI13: 74 | AJ13: =AJ11 -> 113 | AP13: =IF(G13="","",$AQ$1&_xlfn.TEXTJOIN(",",1,G13:I13,K13,L13)&$AR$1) -> {5000,3,1,1,101} | AQ13: =IF(G13="","",$AQ$1&_xlfn.TEXTJOIN(",",1,M13:P13,R13)&$AR$1) -> {5000,3,1,1,103} | AR13: =IF(G13="","",$AQ$1&_xlfn.TEXTJOIN(",",1,S13:V13,X13)&$AR$1) -> {5000,3,1,2,111} | AS13: =IF(G13="","",$AQ$1&_xlfn.TEXTJOIN(",",1,Y13:AB13,AD13)&$AR$1) -> {5000,3,1,1,112} | AT13: =IF(G13="","",$AQ$1&_xlfn.TEXTJOIN(",",1,AE13:AH13,AJ13)&$AR$1) -> {5000,3,1,2,113} | AU13: =IF(AK13="","",IF(G13="","",$AQ$1&_xlfn.TEXTJOIN(",",1,AK13:AO13)&$AR$1)) | AV13: 1022 | AW13: =IF(AU13="","["&_xlfn.TEXTJOIN(",",1,AP13:AT13)&"]","["&_xlfn.TEXTJOIN(",",1,AP13:AU13)&"]") -> [{5000,3,1,1,101},{5000,3,1,1,103},{5000,3,1,2,111},{5000,3,1,1,112},{5000,3,1,2,113}]
B14: 1023 | C14: 关卡1 | D14: =RIGHT(C14,1) -> 1 | F14: 181 | G14: 5000 | H14: 4 | I14: 1 | J14: 3 | K14: 3 | L14: =L12 -> 101 | M14: 5000 | N14: =H14 -> 4 | O14: 1 | P14: 3 | Q14: 53 | R14: =R12 -> 102 | S14: 5000 | T14: =N14 -> 4 | U14: 1 | V14: 3 | W14: 56 | X14: =X12 -> 103 | Y14: 5000 | Z14: =T14 -> 4 | AA14: 1 | AB14: 3 | AC14: 75 | AD14: =AD12 -> 113 | AE14: 5000 | AF14: =Z14 -> 4 | AG14: 1 | AH14: 3 | AI14: 78 | AJ14: =AJ12 -> 111 | AP14: =IF(G14="","",$AQ$1&_xlfn.TEXTJOIN(",",1,G14:I14,K14,L14)&$AR$1) -> {5000,4,1,3,101} | AQ14: =IF(G14="","",$AQ$1&_xlfn.TEXTJOIN(",",1,M14:P14,R14)&$AR$1) -> {5000,4,1,3,102} | AR14: =IF(G14="","",$AQ$1&_xlfn.TEXTJOIN(",",1,S14:V14,X14)&$AR$1) -> {5000,4,1,3,103} | AS14: =IF(G14="","",$AQ$1&_xlfn.TEXTJOIN(",",1,Y14:AB14,AD14)&$AR$1) -> {5000,4,1,3,113} | AT14: =IF(G14="","",$AQ$1&_xlfn.TEXTJOIN(",",1,AE14:AH14,AJ14)&$AR$1) -> {5000,4,1,3,111} | AU14: =IF(AK14="","",IF(G14="","",$AQ$1&_xlfn.TEXTJOIN(",",1,AK14:AO14)&$AR$1)) | AV14: 1023 | AW14: =IF(AU14="","["&_xlfn.TEXTJOIN(",",1,AP14:AT14)&"]","["&_xlfn.TEXTJOIN(",",1,AP14:AU14)&"]") -> [{5000,4,1,3,101},{5000,4,1,3,102},{5000,4,1,3,103},{5000,4,1,3,113},{5000,4,1,3,111}]
B15: 1024 | C15: 关卡1 | D15: =RIGHT(C15,1) -> 1 | F15: 196 | G15: 5000 | H15: 3 | I15: 1 | J15: 2 | K15: 2 | L15: =L13 -> 101 | M15: 5000 | N15: =H15 -> 3 | O15: 1 | P15: 1 | Q15: 54 | R15: =R13 -> 103 | S15: 5000 | T15: =N15 -> 3 | U15: 1 | V15: 2 | W15: 77 | X15: =X13 -> 111 | Y15: 5000 | Z15: =T15 -> 3 | AA15: 1 | AB15: 1 | AC15: 72 | AD15: =AD13 -> 112 | AE15: 5000 | AF15: =Z15 -> 3 | AG15: 1 | AH15: 2 | AI15: 74 | AJ15: =AJ13 -> 113 | AP15: =IF(G15="","",$AQ$1&_xlfn.TEXTJOIN(",",1,G15:I15,K15,L15)&$AR$1) -> {5000,3,1,2,101} | AQ15: =IF(G15="","",$AQ$1&_xlfn.TEXTJOIN(",",1,M15:P15,R15)&$AR$1) -> {5000,3,1,1,103} | AR15: =IF(G15="","",$AQ$1&_xlfn.TEXTJOIN(",",1,S15:V15,X15)&$AR$1) -> {5000,3,1,2,111} | AS15: =IF(G15="","",$AQ$1&_xlfn.TEXTJOIN(",",1,Y15:AB15,AD15)&$AR$1) -> {5000,3,1,1,112} | AT15: =IF(G15="","",$AQ$1&_xlfn.TEXTJOIN(",",1,AE15:AH15,AJ15)&$AR$1) -> {5000,3,1,2,113} | AU15: =IF(AK15="","",IF(G15="","",$AQ$1&_xlfn.TEXTJOIN(",",1,AK15:AO15)&$AR$1)) | AV15: 1024 | AW15: =IF(AU15="","["&_xlfn.TEXTJOIN(",",1,AP15:AT15)&"]","["&_xlfn.TEXTJOIN(",",1,AP15:AU15)&"]") -> [{5000,3,1,2,101},{5000,3,1,1,103},{5000,3,1,2,111},{5000,3,1,1,112},{5000,3,1,2,113}]
... B22: 1031 | C22: 关卡1 | D22: =RIGHT(C22,1) -> 1 | F22: 290 | G22: 5000 | H22: 4 | I22: 1 | J22: 2 | K22: 2 | L22: =L20 -> 101 | M22: 5000 | N22: =H22 -> 4 | O22: 1 | P22: 2 | Q22: 56 | R22: =R20 -> 102 | S22: 5000 | T22: =N22 -> 4 | U22: 1 | V22: 1 | W22: 77 | X22: =X20 -> 103 | Y22: 5000 | Z22: =T22 -> 4 | AA22: 1 | AB22: 2 | AC22: 72 | AD22: =AD20 -> 113 | AE22: 5000 | AF22: =Z22 -> 4 | AG22: 1 | AH22: 2 | AI22: 74 | AJ22: =AJ20 -> 111 | AP22: =IF(G22="","",$AQ$1&_xlfn.TEXTJOIN(",",1,G22:I22,K22,L22)&$AR$1) -> {5000,4,1,2,101} | AQ22: =IF(G22="","",$AQ$1&_xlfn.TEXTJOIN(",",1,M22:P22,R22)&$AR$1) -> {5000,4,1,2,102} | AR22: =IF(G22="","",$AQ$1&_xlfn.TEXTJOIN(",",1,S22:V22,X22)&$AR$1) -> {5000,4,1,1,103} | AS22: =IF(G22="","",$AQ$1&_xlfn.TEXTJOIN(",",1,Y22:AB22,AD22)&$AR$1) -> {5000,4,1,2,113} | AT22: =IF(G22="","",$AQ$1&_xlfn.TEXTJOIN(",",1,AE22:AH22,AJ22)&$AR$1) -> {5000,4,1,2,111} | AU22: =IF(AK22="","",IF(G22="","",$AQ$1&_xlfn.TEXTJOIN(",",1,AK22:AO22)&$AR$1)) | AV22: 1031 | AW22: =IF(AU22="","["&_xlfn.TEXTJOIN(",",1,AP22:AT22)&"]","["&_xlfn.TEXTJOIN(",",1,AP22:AU22)&"]") -> [{5000,4,1,2,101},{5000,4,1,2,102},{5000,4,1,1,103},{5000,4,1,2,113},{5000,4,1,2,111}]
B23: 1111 | C23: 关卡2 | D23: =RIGHT(C23,1) -> 2 | F23: 1 | G23: 5000 | H23: 1 | I23: 1 | J23: 1 | K23: =IF($J23="","",K2+100) -> 101 | L23: =IF(L2="","",L2) -> 101 | M23: 5000 | N23: =H23 -> 1 | O23: 1 | P23: =IF($J23="","",P2+100) -> 101 | Q23: 55 | R23: =IF(R2="","",R2) -> 102 | S23: 5000 | T23: =N23 -> 1 | U23: 1 | V23: =IF($J23="","",V2+100) -> 101 | W23: 60 | X23: =IF(X2="","",X2) -> 103 | Y23: 5000 | Z23: =T23 -> 1 | AA23: 1 | AB23: =IF($J23="","",AB2+100) -> 101 | AC23: 71 | AD23: =IF(AD2="","",AD2) -> 113 | AE23: 5000 | AF23: =Z23 -> 1 | AG23: 1 | AH23: =IF($J23="","",AH2+100) -> 101 | AI23: 76 | AJ23: =IF(AJ2="","",AJ2) -> 111 | AP23: =IF(G23="","",$AQ$1&_xlfn.TEXTJOIN(",",1,G23:I23,K23,L23)&$AR$1) -> {5000,1,1,101,101} | AQ23: =IF(G23="","",$AQ$1&_xlfn.TEXTJOIN(",",1,M23:P23,R23)&$AR$1) -> {5000,1,1,101,102} | AR23: =IF(G23="","",$AQ$1&_xlfn.TEXTJOIN(",",1,S23:V23,X23)&$AR$1) -> {5000,1,1,101,103} | AS23: =IF(G23="","",$AQ$1&_xlfn.TEXTJOIN(",",1,Y23:AB23,AD23)&$AR$1) -> {5000,1,1,101,113} | AT23: =IF(G23="","",$AQ$1&_xlfn.TEXTJOIN(",",1,AE23:AH23,AJ23)&$AR$1) -> {5000,1,1,101,111} | AU23: =IF(AK23="","",IF(G23="","",$AQ$1&_xlfn.TEXTJOIN(",",1,AK23:AO23)&$AR$1)) | AV23: 1111 | AW23: =IF(AU23="","["&_xlfn.TEXTJOIN(",",1,AP23:AT23)&"]","["&_xlfn.TEXTJOIN(",",1,AP23:AU23)&"]") -> [{5000,1,1,101,101},{5000,1,1,101,102},{5000,1,1,101,103},{5000,1,1,101,113},{5000,1,1,101,111}]
B24: 1112 | C24: 关卡2 | D24: =RIGHT(C24,1) -> 2 | F24: 16 | G24: 5000 | H24: 1 | I24: 1 | J24: 1 | K24: =IF($J24="","",K3+100) -> 101 | L24: =IF(L3="","",L3) -> 101 | M24: 5000 | N24: =H24 -> 1 | O24: 1 | P24: =IF($J24="","",P3+100) -> 101 | Q24: 55 | R24: =IF(R3="","",R3) -> 103 | S24: 5000 | T24: =N24 -> 1 | U24: 1 | V24: =IF($J24="","",V3+100) -> 101 | W24: 75 | X24: =IF(X3="","",X3) -> 111 | Y24: 5000 | Z24: =T24 -> 1 | AA24: 1 | AB24: =IF($J24="","",AB3+100) -> 101 | AC24: 73 | AD24: =IF(AD3="","",AD3) -> 112 | AE24: 5000 | AF24: =Z24 -> 1 | AG24: 1 | AH24: =IF($J24="","",AH3+100) -> 101 | AI24: 78 | AJ24: =IF(AJ3="","",AJ3) -> 113 | AP24: =IF(G24="","",$AQ$1&_xlfn.TEXTJOIN(",",1,G24:I24,K24,L24)&$AR$1) -> {5000,1,1,101,101} | AQ24: =IF(G24="","",$AQ$1&_xlfn.TEXTJOIN(",",1,M24:P24,R24)&$AR$1) -> {5000,1,1,101,103} | AR24: =IF(G24="","",$AQ$1&_xlfn.TEXTJOIN(",",1,S24:V24,X24)&$AR$1) -> {5000,1,1,101,111} | AS24: =IF(G24="","",$AQ$1&_xlfn.TEXTJOIN(",",1,Y24:AB24,AD24)&$AR$1) -> {5000,1,1,101,112} | AT24: =IF(G24="","",$AQ$1&_xlfn.TEXTJOIN(",",1,AE24:AH24,AJ24)&$AR$1) -> {5000,1,1,101,113} | AU24: =IF(AK24="","",IF(G24="","",$AQ$1&_xlfn.TEXTJOIN(",",1,AK24:AO24)&$AR$1)) | AV24: 1112 | AW24: =IF(AU24="","["&_xlfn.TEXTJOIN(",",1,AP24:AT24)&"]","["&_xlfn.TEXTJOIN(",",1,AP24:AU24)&"]") -> [{5000,1,1,101,101},{5000,1,1,101,103},{5000,1,1,101,111},{5000,1,1,101,112},{5000,1,1,101,113}]
B25: 1113 | C25: 关卡2 | D25: =RIGHT(C25,1) -> 2 | F25: 31 | G25: 5000 | H25: 2 | I25: 1 | J25: 1 | K25: =IF($J25="","",K4+100) -> 101 | L25: =IF(L4="","",L4) -> 101 | M25: 5000 | N25: =H25 -> 2 | O25: 1 | P25: =IF($J25="","",P4+100) -> 101 | Q25: 55 | R25: =IF(R4="","",R4) -> 102 | S25: 5000 | T25: =N25 -> 2 | U25: 1 | V25: =IF($J25="","",V4+100) -> 101 | W25: 58 | X25: =IF(X4="","",X4) -> 103 | Y25: 5000 | Z25: =T25 -> 2 | AA25: 1 | AB25: =IF($J25="","",AB4+100) -> 101 | AC25: 76 | AD25: =IF(AD4="","",AD4) -> 113 | AE25: 5000 | AF25: =Z25 -> 2 | AG25: 1 | AH25: =IF($J25="","",AH4+100) -> 101 | AI25: 79 | AJ25: =IF(AJ4="","",AJ4) -> 111 | AP25: =IF(G25="","",$AQ$1&_xlfn.TEXTJOIN(",",1,G25:I25,K25,L25)&$AR$1) -> {5000,2,1,101,101} | AQ25: =IF(G25="","",$AQ$1&_xlfn.TEXTJOIN(",",1,M25:P25,R25)&$AR$1) -> {5000,2,1,101,102} | AR25: =IF(G25="","",$AQ$1&_xlfn.TEXTJOIN(",",1,S25:V25,X25)&$AR$1) -> {5000,2,1,101,103} | AS25: =IF(G25="","",$AQ$1&_xlfn.TEXTJOIN(",",1,Y25:AB25,AD25)&$AR$1) -> {5000,2,1,101,113} | AT25: =IF(G25="","",$AQ$1&_xlfn.TEXTJOIN(",",1,AE25:AH25,AJ25)&$AR$1) -> {5000,2,1,101,111} | AU25: =IF(AK25="","",IF(G25="","",$AQ$1&_xlfn.TEXTJOIN(",",1,AK25:AO25)&$AR$1)) | AV25: 1113 | AW25: =IF(AU25="","["&_xlfn.TEXTJOIN(",",1,AP25:AT25)&"]","["&_xlfn.TEXTJOIN(",",1,AP25:AU25)&"]") -> [{5000,2,1,101,101},{5000,2,1,101,102},{5000,2,1,101,103},{5000,2,1,101,113},{5000,2,1,101,111}]
B26: 1114 | C26: 关卡2 | D26: =RIGHT(C26,1) -> 2 | F26: 46 | G26: 5000 | H26: 2 | I26: 1 | J26: 1 | K26: =IF($J26="","",K5+100) -> 101 | L26: =IF(L5="","",L5) -> 101 | M26: 5000 | N26: =H26 -> 2 | O26: 1 | P26: =IF($J26="","",P5+100) -> 101 | Q26: 55 | R26: =IF(R5="","",R5) -> 103 | S26: 5000 | T26: =N26 -> 2 | U26: 1 | V26: =IF($J26="","",V5+100) -> 102 | W26: 76 | X26: =IF(X5="","",X5) -> 111 | Y26: 5000 | Z26: =T26 -> 2 | AA26: 1 | AB26: =IF($J26="","",AB5+100) -> 101 | AC26: 71 | AD26: =IF(AD5="","",AD5) -> 112 | AE26: 5000 | AF26: =Z26 -> 2 | AG26: 1 | AH26: =IF($J26="","",AH5+100) -> 101 | AI26: 71 | AJ26: =IF(AJ5="","",AJ5) -> 113 | AP26: =IF(G26="","",$AQ$1&_xlfn.TEXTJOIN(",",1,G26:I26,K26,L26)&$AR$1) -> {5000,2,1,101,101} | AQ26: =IF(G26="","",$AQ$1&_xlfn.TEXTJOIN(",",1,M26:P26,R26)&$AR$1) -> {5000,2,1,101,103} | AR26: =IF(G26="","",$AQ$1&_xlfn.TEXTJOIN(",",1,S26:V26,X26)&$AR$1) -> {5000,2,1,102,111} | AS26: =IF(G26="","",$AQ$1&_xlfn.TEXTJOIN(",",1,Y26:AB26,AD26)&$AR$1) -> {5000,2,1,101,112} | AT26: =IF(G26="","",$AQ$1&_xlfn.TEXTJOIN(",",1,AE26:AH26,AJ26)&$AR$1) -> {5000,2,1,101,113} | AU26: =IF(AK26="","",IF(G26="","",$AQ$1&_xlfn.TEXTJOIN(",",1,AK26:AO26)&$AR$1)) | AV26: 1114 | AW26: =IF(AU26="","["&_xlfn.TEXTJOIN(",",1,AP26:AT26)&"]","["&_xlfn.TEXTJOIN(",",1,AP26:AU26)&"]") -> [{5000,2,1,101,101},{5000,2,1,101,103},{5000,2,1,102,111},{5000,2,1,101,112},{5000,2,1,101,113}]
B27: 1115 | C27: 关卡2 | D27: =RIGHT(C27,1) -> 2 | F27: 61 | G27: 5000 | H27: 2 | I27: 1 | J27: 3 | K27: =IF($J27="","",K6+100) -> 103 | L27: =IF(L6="","",L6) -> 101 | M27: 5000 | N27: =H27 -> 2 | O27: 1 | P27: =IF($J27="","",P6+100) -> 103 | Q27: 1 | R27: =IF(R6="","",R6) -> 102 | S27: 5000 | T27: =N27 -> 2 | U27: 1 | V27: =IF($J27="","",V6+100) -> 103 | W27: 1 | X27: =IF(X6="","",X6) -> 103 | Y27: 5000 | Z27: =T27 -> 2 | AA27: 1 | AB27: =IF($J27="","",AB6+100) -> 103 | AC27: 1 | AD27: =IF(AD6="","",AD6) -> 113 | AE27: 5000 | AF27: =Z27 -> 2 | AG27: 1 | AH27: =IF($J27="","",AH6+100) -> 103 | AI27: 1 | AJ27: =IF(AJ6="","",AJ6) -> 111 | AP27: =IF(G27="","",$AQ$1&_xlfn.TEXTJOIN(",",1,G27:I27,K27,L27)&$AR$1) -> {5000,2,1,103,101} | AQ27: =IF(G27="","",$AQ$1&_xlfn.TEXTJOIN(",",1,M27:P27,R27)&$AR$1) -> {5000,2,1,103,102} | AR27: =IF(G27="","",$AQ$1&_xlfn.TEXTJOIN(",",1,S27:V27,X27)&$AR$1) -> {5000,2,1,103,103} | AS27: =IF(G27="","",$AQ$1&_xlfn.TEXTJOIN(",",1,Y27:AB27,AD27)&$AR$1) -> {5000,2,1,103,113} | AT27: =IF(G27="","",$AQ$1&_xlfn.TEXTJOIN(",",1,AE27:AH27,AJ27)&$AR$1) -> {5000,2,1,103,111} | AU27: =IF(AK27="","",IF(G27="","",$AQ$1&_xlfn.TEXTJOIN(",",1,AK27:AO27)&$AR$1)) | AV27: 1115 | AW27: =IF(AU27="","["&_xlfn.TEXTJOIN(",",1,AP27:AT27)&"]","["&_xlfn.TEXTJOIN(",",1,AP27:AU27)&"]") -> [{5000,2,1,103,101},{5000,2,1,103,102},{5000,2,1,103,103},{5000,2,1,103,113},{5000,2,1,103,111}]
B28: 1116 | C28: 关卡2 | D28: =RIGHT(C28,1) -> 2 | F28: 76 | G28: 5000 | H28: 2 | I28: 1 | J28: 1 | K28: =IF($J28="","",K7+100) -> 101 | L28: =IF(L7="","",L7) -> 101 | M28: 5000 | N28: =H28 -> 2 | O28: 1 | P28: =IF($J28="","",P7+100) -> 101 | Q28: 59 | R28: =IF(R7="","",R7) -> 103 | S28: 5000 | T28: =N28 -> 2 | U28: 1 | V28: =IF($J28="","",V7+100) -> 102 | W28: 71 | X28: =IF(X7="","",X7) -> 111 | Y28: 5000 | Z28: =T28 -> 2 | AA28: 1 | AB28: =IF($J28="","",AB7+100) -> 101 | AC28: 71 | AD28: =IF(AD7="","",AD7) -> 112 | AE28: 5000 | AF28: =Z28 -> 2 | AG28: 1 | AH28: =IF($J28="","",AH7+100) -> 101 | AI28: 79 | AJ28: =IF(AJ7="","",AJ7) -> 113 | AP28: =IF(G28="","",$AQ$1&_xlfn.TEXTJOIN(",",1,G28:I28,K28,L28)&$AR$1) -> {5000,2,1,101,101} | AQ28: =IF(G28="","",$AQ$1&_xlfn.TEXTJOIN(",",1,M28:P28,R28)&$AR$1) -> {5000,2,1,101,103} | AR28: =IF(G28="","",$AQ$1&_xlfn.TEXTJOIN(",",1,S28:V28,X28)&$AR$1) -> {5000,2,1,102,111} | AS28: =IF(G28="","",$AQ$1&_xlfn.TEXTJOIN(",",1,Y28:AB28,AD28)&$AR$1) -> {5000,2,1,101,112} | AT28: =IF(G28="","",$AQ$1&_xlfn.TEXTJOIN(",",1,AE28:AH28,AJ28)&$AR$1) -> {5000,2,1,101,113} | AU28: =IF(AK28="","",IF(G28="","",$AQ$1&_xlfn.TEXTJOIN(",",1,AK28:AO28)&$AR$1)) | AV28: 1116 | AW28: =IF(AU28="","["&_xlfn.TEXTJOIN(",",1,AP28:AT28)&"]","["&_xlfn.TEXTJOIN(",",1,AP28:AU28)&"]") -> [{5000,2,1,101,101},{5000,2,1,101,103},{5000,2,1,102,111},{5000,2,1,101,112},{5000,2,1,101,113}]
B29: 1117 | C29: 关卡2 | D29: =RIGHT(C29,1) -> 2 | F29: 91 | G29: 5000 | H29: 2 | I29: 1 | J29: 1 | K29: =IF($J29="","",K8+100) -> 101 | L29: =IF(L8="","",L8) -> 101 | M29: 5000 | N29: =H29 -> 2 | O29: 1 | P29: =IF($J29="","",P8+100) -> 101 | Q29: 54 | R29: =IF(R8="","",R8) -> 102 | S29: 5000 | T29: =N29 -> 2 | U29: 1 | V29: =IF($J29="","",V8+100) -> 102 | W29: 51 | X29: =IF(X8="","",X8) -> 103 | Y29: 5000 | Z29: =T29 -> 2 | AA29: 1 | AB29: =IF($J29="","",AB8+100) -> 101 | AC29: 71 | AD29: =IF(AD8="","",AD8) -> 113 | AE29: 5000 | AF29: =Z29 -> 2 | AG29: 1 | AH29: =IF($J29="","",AH8+100) -> 102 | AI29: 77 | AJ29: =IF(AJ8="","",AJ8) -> 111 | AP29: =IF(G29="","",$AQ$1&_xlfn.TEXTJOIN(",",1,G29:I29,K29,L29)&$AR$1) -> {5000,2,1,101,101} | AQ29: =IF(G29="","",$AQ$1&_xlfn.TEXTJOIN(",",1,M29:P29,R29)&$AR$1) -> {5000,2,1,101,102} | AR29: =IF(G29="","",$AQ$1&_xlfn.TEXTJOIN(",",1,S29:V29,X29)&$AR$1) -> {5000,2,1,102,103} | AS29: =IF(G29="","",$AQ$1&_xlfn.TEXTJOIN(",",1,Y29:AB29,AD29)&$AR$1) -> {5000,2,1,101,113} | AT29: =IF(G29="","",$AQ$1&_xlfn.TEXTJOIN(",",1,AE29:AH29,AJ29)&$AR$1) -> {5000,2,1,102,111} | AU29: =IF(AK29="","",IF(G29="","",$AQ$1&_xlfn.TEXTJOIN(",",1,AK29:AO29)&$AR$1)) | AV29: 1117 | AW29: =IF(AU29="","["&_xlfn.TEXTJOIN(",",1,AP29:AT29)&"]","["&_xlfn.TEXTJOIN(",",1,AP29:AU29)&"]") -> [{5000,2,1,101,101},{5000,2,1,101,102},{5000,2,1,102,103},{5000,2,1,101,113},{5000,2,1,102,111}]
B30: 1118 | C30: 关卡2 | D30: =RIGHT(C30,1) -> 2 | F30: 106 | G30: 5000 | H30: 2 | I30: 1 | J30: 1 | K30: =IF($J30="","",K9+100) -> 101 | L30: =IF(L9="","",L9) -> 101 | M30: 5000 | N30: =H30 -> 2 | O30: 1 | P30: =IF($J30="","",P9+100) -> 101 | Q30: 55 | R30: =IF(R9="","",R9) -> 103 | S30: 5000 | T30: =N30 -> 2 | U30: 1 | V30: =IF($J30="","",V9+100) -> 102 | W30: 73 | X30: =IF(X9="","",X9) -> 111 | Y30: 5000 | Z30: =T30 -> 2 | AA30: 1 | AB30: =IF($J30="","",AB9+100) -> 101 | AC30: 78 | AD30: =IF(AD9="","",AD9) -> 112 | AE30: 5000 | AF30: =Z30 -> 2 | AG30: 1 | AH30: =IF($J30="","",AH9+100) -> 102 | AI30: 71 | AJ30: =IF(AJ9="","",AJ9) -> 113 | AP30: =IF(G30="","",$AQ$1&_xlfn.TEXTJOIN(",",1,G30:I30,K30,L30)&$AR$1) -> {5000,2,1,101,101} | AQ30: =IF(G30="","",$AQ$1&_xlfn.TEXTJOIN(",",1,M30:P30,R30)&$AR$1) -> {5000,2,1,101,103} | AR30: =IF(G30="","",$AQ$1&_xlfn.TEXTJOIN(",",1,S30:V30,X30)&$AR$1) -> {5000,2,1,102,111} | AS30: =IF(G30="","",$AQ$1&_xlfn.TEXTJOIN(",",1,Y30:AB30,AD30)&$AR$1) -> {5000,2,1,101,112} | AT30: =IF(G30="","",$AQ$1&_xlfn.TEXTJOIN(",",1,AE30:AH30,AJ30)&$AR$1) -> {5000,2,1,102,113} | AU30: =IF(AK30="","",IF(G30="","",$AQ$1&_xlfn.TEXTJOIN(",",1,AK30:AO30)&$AR$1)) | AV30: 1118 | AW30: =IF(AU30="","["&_xlfn.TEXTJOIN(",",1,AP30:AT30)&"]","["&_xlfn.TEXTJOIN(",",1,AP30:AU30)&"]") -> [{5000,2,1,101,101},{5000,2,1,101,103},{5000,2,1,102,111},{5000,2,1,101,112},{5000,2,1,102,113}]
B31: 1119 | C31: 关卡2 | D31: =RIGHT(C31,1) -> 2 | F31: 121 | G31: 5000 | H31: 3 | I31: 1 | J31: 3 | K31: =IF($J31="","",K10+100) -> 103 | L31: =IF(L10="","",L10) -> 101 | M31: 5000 | N31: =H31 -> 3 | O31: 1 | P31: =IF($J31="","",P10+100) -> 103 | Q31: 54 | R31: =IF(R10="","",R10) -> 102 | S31: 5000 | T31: =N31 -> 3 | U31: 1 | V31: =IF($J31="","",V10+100) -> 103 | W31: 51 | X31: =IF(X10="","",X10) -> 103 | Y31: 5000 | Z31: =T31 -> 3 | AA31: 1 | AB31: =IF($J31="","",AB10+100) -> 103 | AC31: 71 | AD31: =IF(AD10="","",AD10) -> 113 | AE31: 5000 | AF31: =Z31 -> 3 | AG31: 1 | AH31: =IF($J31="","",AH10+100) -> 103 | AI31: 79 | AJ31: =IF(AJ10="","",AJ10) -> 111 | AP31: =IF(G31="","",$AQ$1&_xlfn.TEXTJOIN(",",1,G31:I31,K31,L31)&$AR$1) -> {5000,3,1,103,101} | AQ31: =IF(G31="","",$AQ$1&_xlfn.TEXTJOIN(",",1,M31:P31,R31)&$AR$1) -> {5000,3,1,103,102} | AR31: =IF(G31="","",$AQ$1&_xlfn.TEXTJOIN(",",1,S31:V31,X31)&$AR$1) -> {5000,3,1,103,103} | AS31: =IF(G31="","",$AQ$1&_xlfn.TEXTJOIN(",",1,Y31:AB31,AD31)&$AR$1) -> {5000,3,1,103,113} | AT31: =IF(G31="","",$AQ$1&_xlfn.TEXTJOIN(",",1,AE31:AH31,AJ31)&$AR$1) -> {5000,3,1,103,111} | AU31: =IF(AK31="","",IF(G31="","",$AQ$1&_xlfn.TEXTJOIN(",",1,AK31:AO31)&$AR$1)) | AV31: 1119 | AW31: =IF(AU31="","["&_xlfn.TEXTJOIN(",",1,AP31:AT31)&"]","["&_xlfn.TEXTJOIN(",",1,AP31:AU31)&"]") -> [{5000,3,1,103,101},{5000,3,1,103,102},{5000,3,1,103,103},{5000,3,1,103,113},{5000,3,1,103,111}]
B32: 1120 | C32: 关卡2 | D32: =RIGHT(C32,1) -> 2 | F32: 136 | G32: 5000 | H32: 3 | I32: 1 | J32: 1 | K32: =IF($J32="","",K11+100) -> 101 | L32: =IF(L11="","",L11) -> 101 | M32: 5000 | N32: =H32 -> 3 | O32: 1 | P32: =IF($J32="","",P11+100) -> 101 | Q32: 54 | R32: =IF(R11="","",R11) -> 103 | S32: 5000 | T32: =N32 -> 3 | U32: 1 | V32: =IF($J32="","",V11+100) -> 102 | W32: 76 | X32: =IF(X11="","",X11) -> 111 | Y32: 5000 | Z32: =T32 -> 3 | AA32: 1 | AB32: =IF($J32="","",AB11+100) -> 101 | AC32: 72 | AD32: =IF(AD11="","",AD11) -> 112 | AE32: 5000 | AF32: =Z32 -> 3 | AG32: 1 | AH32: =IF($J32="","",AH11+100) -> 102 | AI32: 74 | AJ32: =IF(AJ11="","",AJ11) -> 113 | AP32: =IF(G32="","",$AQ$1&_xlfn.TEXTJOIN(",",1,G32:I32,K32,L32)&$AR$1) -> {5000,3,1,101,101} | AQ32: =IF(G32="","",$AQ$1&_xlfn.TEXTJOIN(",",1,M32:P32,R32)&$AR$1) -> {5000,3,1,101,103} | AR32: =IF(G32="","",$AQ$1&_xlfn.TEXTJOIN(",",1,S32:V32,X32)&$AR$1) -> {5000,3,1,102,111} | AS32: =IF(G32="","",$AQ$1&_xlfn.TEXTJOIN(",",1,Y32:AB32,AD32)&$AR$1) -> {5000,3,1,101,112} | AT32: =IF(G32="","",$AQ$1&_xlfn.TEXTJOIN(",",1,AE32:AH32,AJ32)&$AR$1) -> {5000,3,1,102,113} | AU32: =IF(AK32="","",IF(G32="","",$AQ$1&_xlfn.TEXTJOIN(",",1,AK32:AO32)&$AR$1)) | AV32: 1120 | AW32: =IF(AU32="","["&_xlfn.TEXTJOIN(",",1,AP32:AT32)&"]","["&_xlfn.TEXTJOIN(",",1,AP32:AU32)&"]") -> [{5000,3,1,101,101},{5000,3,1,101,103},{5000,3,1,102,111},{5000,3,1,101,112},{5000,3,1,102,113}]
