Workbook

Sheet Sheet1
A1: 随机id【KEY】 | B1: 所属关卡 | C1: 所属类型 | D1: 注释字段 | E1: 调用怪物形象id | F1: 怪物形象图片 | G1: 怪物属性 | H1: 怪物类型 0小怪 1精英 2boss | I1: 怪物特性id | J1: 攻击类型 0碰撞 1自爆 | K1: 是否相互拥挤0否 1是 | L1: 技能类型（1 远程 ） | M1: 攻击距离 | N1: 分裂怪物id | O1: 召唤怪物id | P1: 击杀掉落 | Q1: 普攻id(技能id+施法时间) | R1: 怪物击杀经验 | S1: 怪物击杀获取能量
A2: both | B2: both | C2: both | E2: both | F2: client | G2: both | H2: both | I2: both | J2: both | K2: client | L2: client | M2: client | N2: client | O2: client | P2: both | Q2: both | R2: client | S2: client
A3: id | B3: stageId | C3: type | D3: string | E3: modelId | F3: modelPicture | G3: monsterPro | H3: monsterType | I3: characterId | J3: atkType | K3: crowd | L3: skillType | M3: atkDistance | N3: splitModelId | O3: summonMonsterId | P3: drop | Q3: atkId | R3: killExp | S3: killEnergy
A4: int | B4: int | C4: int | D4: string | E4: int | F4: string | G4: [Attribute] | H4: int | I4: [int] | J4: int | K4: int | L4: int | M4: int | N4: int | O4: [int] | P4: [Reward] | Q4: [MonsterSkill] | R4: int | S4: int
B5: index
A6: 101 | B6: 1 | C6: 1 | D6: 关卡1怪物1 | E6: 101 | G6: [{cd,3000},{hp,60},{atk,6},{spd,8500}] | H6: 0 | J6: 0 | K6: 0 | R6: 65 | S6: 2
A7: 102 | B7: 1 | C7: 2 | D7: 关卡1怪物2 | E7: 100 | G7: [{cd,3000},{hp,50},{atk,4},{spd,8500}] | H7: 0 | I7: [60002] | J7: 0 | K7: 0 | N7: 2001 | R7: 65 | S7: 2
A8: 103 | B8: 1 | C8: 3 | D8: 关卡1怪物3 | E8: 101 | G8: [{cd,3000},{hp,40},{atk,6},{spd,8500}] | H8: 0 | J8: 0 | K8: 0 | R8: 65 | S8: 2
A9: 121 | B9: 1 | C9: 4 | D9: 关卡1BOSS1 | E9: 501 | G9: [{cd,3000},{hp,1350},{atk,15},{spd,8500}] | H9: 2 | J9: 0 | K9: 0 | R9: 65 | S9: 2
A10: 131 | B10: 1 | C10: 5 | D10: 关卡1BOSS2 | E10: 501 | G10: [{cd,3000},{hp,2250},{atk,30},{spd,8500}] | H10: 2 | J10: 0 | K10: 0 | R10: 65 | S10: 2
A11: =A6+100 -> 201 | B11: 2 | C11: 1 | D11: 关卡2怪物1 | E11: 101 | G11: [{cd,3000},{hp,60},{atk,6},{spd,8500}] | H11: =H6 -> 0 | J11: 0 | K11: 0 | R11: 45 | S11: 2
A12: =A7+100 -> 202 | B12: 2 | C12: 2 | D12: 关卡2怪物2 | E12: 100 | G12: [{cd,3000},{hp,50},{atk,4},{spd,8500}] | H12: =H7 -> 0 | I12: [60002] | J12: 0 | K12: 0 | N12: 2001 | R12: 45 | S12: 2
A13: =A8+100 -> 203 | B13: 2 | C13: 3 | D13: 关卡2怪物3 | E13: 102 | G13: [{cd,3000},{hp,40},{atk,3},{spd,8500}] | H13: =H8 -> 0 | J13: 0 | K13: 0 | L13: 1 | Q13: [{50011,6}] | R13: 45 | S13: 2
A14: =A9+100 -> 221 | B14: 2 | C14: 4 | D14: 关卡2BOSS1 | E14: 501 | G14: [{cd,3000},{hp,1350},{atk,15},{spd,8500}] | H14: =H9 -> 2 | J14: 0 | K14: 0 | R14: 100 | S14: 2
A15: =A10+100 -> 231 | B15: 2 | C15: 5 | D15: 关卡2BOSS2 | E15: 501 | G15: [{cd,3000},{hp,2250},{atk,30},{spd,8500}] | H15: =H10 -> 2 | J15: 0 | K15: 0 | R15: 100 | S15: 2
A16: =A11+100 -> 301 | B16: 3 | C16: 1 | D16: 关卡3怪物1 | E16: 103 | G16: [{cd,3000},{hp,60},{atk,6},{spd,8500}] | H16: =H11 -> 0 | I16: [60001] | J16: 0 | K16: 0 | R16: 37 | S16: 2
A17: =A12+100 -> 302 | B17: 3 | C17: 2 | D17: 关卡3怪物2 | E17: 104 | G17: [{cd,3000},{hp,50},{atk,9},{spd,8500}] | H17: =H12 -> 0 | J17: 0 | K17: 0 | R17: 37 | S17: 2
A18: =A13+100 -> 303 | B18: 3 | C18: 3 | D18: 关卡3怪物3 | E18: 104 | G18: [{cd,3000},{hp,40},{atk,9},{spd,8500}] | H18: =H13 -> 0 | J18: 0 | K18: 0 | R18: 37 | S18: 2
A19: =A14+100 -> 321 | B19: 3 | C19: 4 | D19: 关卡3BOSS1 | E19: 504 | G19: [{cd,3000},{hp,1350},{atk,22},{spd,8500}] | H19: =H14 -> 2 | J19: 0 | K19: 0 | R19: 120 | S19: 2
A20: =A15+100 -> 331 | B20: 3 | C20: 5 | D20: 关卡3BOSS2 | E20: 504 | G20: [{cd,3000},{hp,2250},{atk,45},{spd,8500}] | H20: =H15 -> 2 | J20: 0 | K20: 0 | R20: 120 | S20: 2
A21: =A16+100 -> 401 | B21: 4 | C21: 1 | D21: 关卡4怪物1 | E21: 103 | G21: [{cd,3000},{hp,80},{atk,6},{spd,8500}] | H21: =H16 -> 0 | I21: [60001] | J21: 0 | K21: 0 | R21: 35 | S21: 2
A22: =A17+100 -> 402 | B22: 4 | C22: 2 | D22: 关卡4怪物2 | E22: 104 | G22: [{cd,3000},{hp,70},{atk,9},{spd,8500}] | H22: =H17 -> 0 | J22: 0 | K22: 0 | R22: 35 | S22: 2
A23: =A18+100 -> 403 | B23: 4 | C23: 3 | D23: 关卡4怪物3 | E23: 106 | G23: [{cd,3000},{hp,60},{atk,5},{spd,8500}] | H23: =H18 -> 0 | I23: [60002] | J23: 0 | K23: 0 | L23: 1 | N23: 2002 | Q23: [{50012,6}] | R23: 35 | S23: 2
A24: =A19+100 -> 421 | B24: 4 | C24: 4 | D24: 关卡4BOSS1 | E24: 503 | G24: [{cd,3000},{hp,1800},{atk,15},{spd,8500}] | H24: =H19 -> 2 | I24: [60001] | J24: 0 | K24: 0 | R24: 200 | S24: 2
A25: =A20+100 -> 431 | B25: 4 | C25: 5 | D25: 关卡4BOSS2 | E25: 503 | G25: [{cd,3000},{hp,3000},{atk,30},{spd,8500}] | H25: =H20 -> 2 | I25: [60001] | J25: 0 | K25: 0 | R25: 200 | S25: 2
A26: =A21+100 -> 501 | B26: 5 | C26: 1 | D26: 关卡5怪物1 | E26: 100 | G26: [{cd,3000},{hp,100},{atk,4},{spd,8500}] | H26: =H21 -> 0 | I26: [60002] | J26: 0 | K26: 0 | N26: 2001 | R26: 35 | S26: 2
A27: =A22+100 -> 502 | B27: 5 | C27: 2 | D27: 关卡5怪物2 | E27: 102 | G27: [{cd,3000},{hp,90},{atk,3},{spd,8500}] | H27: =H22 -> 0 | J27: 0 | K27: 0 | L27: 1 | Q27: [{50011,6}] | R27: 35 | S27: 2
A28: =A23+100 -> 503 | B28: 5 | C28: 3 | D28: 关卡5怪物3 | E28: 105 | G28: [{cd,3000},{hp,80},{atk,6},{spd,8500}] | H28: =H23 -> 0 | I28: [60003] | J28: 0 | K28: 0 | R28: 35 | S28: 2
A29: =A24+100 -> 521 | B29: 5 | C29: 4 | D29: 关卡5BOSS1 | E29: 502 | G29: [{cd,3000},{hp,2250},{atk,10},{spd,8500}] | H29: =H24 -> 2 | J29: 0 | K29: 0 | L29: 1 | Q29: [{50021,6}] | R29: 150 | S29: 2
A30: =A25+100 -> 531 | B30: 5 | C30: 5 | D30: 关卡5BOSS2 | E30: 500 | G30: [{cd,3000},{hp,3750},{atk,20},{spd,8500}] | H30: =H25 -> 2 | I30: [60002] | J30: 0 | K30: 0 | R30: 150 | S30: 2
A31: =A26+100 -> 601 | B31: 6 | C31: 1 | D31: 关卡6怪物1 | E31: 100 | G31: [{cd,3000},{hp,120},{atk,4},{spd,8500}] | H31: =H26 -> 0 | I31: [60002] | J31: 0 | K31: 0 | N31: 2001 | R31: 40 | S31: 2
A32: =A27+100 -> 602 | B32: 6 | C32: 2 | D32: 关卡6怪物2 | E32: 105 | G32: [{cd,3000},{hp,110},{atk,6},{spd,8500}] | H32: =H27 -> 0 | I32: [60003] | J32: 0 | K32: 0 | R32: 40 | S32: 2
A33: =A28+100 -> 603 | B33: 6 | C33: 3 | D33: 关卡6怪物3 | E33: 102 | G33: [{cd,3000},{hp,100},{atk,3},{spd,8500}] | H33: =H28 -> 0 | J33: 0 | K33: 0 | L33: 1 | Q33: [{50011,6}] | R33: 40 | S33: 2
A34: =A29+100 -> 621 | B34: 6 | C34: 4 | D34: 关卡6BOSS1 | E34: 502 | G34: [{cd,3000},{hp,2700},{atk,10},{spd,8500}] | H34: =H29 -> 2 | J34: 0 | K34: 0 | L34: 1 | Q34: [{50021,6}] | R34: 100 | S34: 2
A35: =A30+100 -> 631 | B35: 6 | C35: 5 | D35: 关卡6BOSS2 | E35: 502 | G35: [{cd,3000},{hp,4500},{atk,21},{spd,8500}] | H35: =H30 -> 2 | J35: 0 | K35: 0 | L35: 1 | Q35: [{50021,6}] | R35: 100 | S35: 2
A36: =A31+100 -> 701 | B36: 7 | C36: 1 | D36: 关卡7怪物1 | E36: 104 | G36: [{cd,3000},{hp,140},{atk,9},{spd,8500}] | H36: =H31 -> 0 | J36: 0 | K36: 0 | R36: 35 | S36: 2
A37: =A32+100 -> 702 | B37: 7 | C37: 2 | D37: 关卡7怪物2 | E37: 106 | G37: [{cd,3000},{hp,130},{atk,5},{spd,8500}] | H37: =H32 -> 0 | I37: [60002] | J37: 0 | K37: 0 | L37: 1 | N37: 2002 | Q37: [{50012,6}] | R37: 35 | S37: 2
A38: =A33+100 -> 703 | B38: 7 | C38: 3 | D38: 关卡7怪物3 | E38: 107 | G38: [{cd,3000},{hp,120},{atk,4},{spd,8500}] | H38: =H33 -> 0 | I38: [60004] | J38: 0 | K38: 0 | L38: 1 | Q38: [{50013,6}] | R38: 35 | S38: 2
A39: =A34+100 -> 721 | B39: 7 | C39: 4 | D39: 关卡7BOSS1 | E39: 503 | G39: [{cd,3000},{hp,3150},{atk,15},{spd,8500}] | H39: =H34 -> 2 | I39: [60001] | J39: 0 | K39: 0 | R39: 100 | S39: 2
A40: =A35+100 -> 731 | B40: 7 | C40: 5 | D40: 关卡7BOSS2 | E40: 503 | G40: [{cd,3000},{hp,5250},{atk,30},{spd,8500}] | H40: =H35 -> 2 | I40: [60001] | J40: 0 | K40: 0 | R40: 100 | S40: 2
...

Sheet Sheet2
V1: {downUnderPhAtk,5000}
C2: { | D2: , | E2: } | V2: {downUnderMagicAtk,5000}
A3: 怪物id | B3: 关卡 | C3: cd | D3: hp | E3: atk | F3: spd | G3: ySpd
A4: =Sheet1!E6 -> 101 | B4: 1 | C4: 3000 | D4: =VLOOKUP(B4,[1]怪物!$N$34:$Q$43,2,0) -> 60 | E4: =VLOOKUP(A4,[1]怪物!$N$3:$Q$13,4,0) -> 6 | F4: =VLOOKUP(A4,$W:$AB,6,0) -> 8500 | H4: =$C$2&C$3&$D$2&C4&$E$2 -> {cd,3000} | I4: =$C$2&D$3&$D$2&D4&$E$2 -> {hp,60} | J4: =$C$2&E$3&$D$2&E4&$E$2 -> {atk,6} | K4: =$C$2&F$3&$D$2&F4&$E$2 -> {spd,8500} | L4: =IF(VLOOKUP(A4,$W:$AC,7,0)=0,"",VLOOKUP(A4,$W:$AC,7,0)) | O4: ="["&_xlfn.TEXTJOIN(",",1,H4:M4)&"]" -> [{cd,3000},{hp,60},{atk,6},{spd,8500}] | W4: 100 | Y4: 2001 | AA4: [60002] | AB4: 8500
A5: =Sheet1!E7 -> 100 | B5: 1 | C5: 3000 | D5: =VLOOKUP(B5,[1]怪物!$N$34:$Q$43,3,0) -> 50 | E5: =VLOOKUP(A5,[1]怪物!$N$3:$Q$13,4,0) -> 4 | F5: =VLOOKUP(A5,$W:$AB,6,0) -> 8500 | H5: =$C$2&C$3&$D$2&C5&$E$2 -> {cd,3000} | I5: =$C$2&D$3&$D$2&D5&$E$2 -> {hp,50} | J5: =$C$2&E$3&$D$2&E5&$E$2 -> {atk,4} | K5: =$C$2&F$3&$D$2&F5&$E$2 -> {spd,8500} | L5: =IF(VLOOKUP(A5,$W:$AC,7,0)=0,"",VLOOKUP(A5,$W:$AC,7,0)) | O5: ="["&_xlfn.TEXTJOIN(",",1,H5:M5)&"]" -> [{cd,3000},{hp,50},{atk,4},{spd,8500}] | W5: 101 | AB5: 8500
A6: =Sheet1!E8 -> 101 | B6: 1 | C6: 3000 | D6: =VLOOKUP(B6,[1]怪物!$N$34:$Q$43,4,0) -> 40 | E6: =VLOOKUP(A6,[1]怪物!$N$3:$Q$13,4,0) -> 6 | F6: =VLOOKUP(A6,$W:$AB,6,0) -> 8500 | H6: =$C$2&C$3&$D$2&C6&$E$2 -> {cd,3000} | I6: =$C$2&D$3&$D$2&D6&$E$2 -> {hp,40} | J6: =$C$2&E$3&$D$2&E6&$E$2 -> {atk,6} | K6: =$C$2&F$3&$D$2&F6&$E$2 -> {spd,8500} | L6: =IF(VLOOKUP(A6,$W:$AC,7,0)=0,"",VLOOKUP(A6,$W:$AC,7,0)) | O6: ="["&_xlfn.TEXTJOIN(",",1,H6:M6)&"]" -> [{cd,3000},{hp,40},{atk,6},{spd,8500}] | W6: 102 | X6: 1 | Z6: [{50011,6}] | AB6: 8500
A7: =Sheet1!E9 -> 501 | B7: 1 | C7: 3000 | D7: =VLOOKUP(B7,[1]怪物!$U$34:$W$43,2,0) -> 1350 | E7: =VLOOKUP(A7,[1]怪物!$R$3:$T$13,2,0) -> 15 | F7: =VLOOKUP(A7,$W:$AB,6,0) -> 8500 | H7: =$C$2&C$3&$D$2&C7&$E$2 -> {cd,3000} | I7: =$C$2&D$3&$D$2&D7&$E$2 -> {hp,1350} | J7: =$C$2&E$3&$D$2&E7&$E$2 -> {atk,15} | K7: =$C$2&F$3&$D$2&F7&$E$2 -> {spd,8500} | L7: =IF(VLOOKUP(A7,$W:$AC,7,0)=0,"",VLOOKUP(A7,$W:$AC,7,0)) | O7: ="["&_xlfn.TEXTJOIN(",",1,H7:M7)&"]" -> [{cd,3000},{hp,1350},{atk,15},{spd,8500}] | W7: 103 | AA7: [60001] | AB7: 8500
A8: =Sheet1!E10 -> 501 | B8: 1 | C8: 3000 | D8: =VLOOKUP(B8,[1]怪物!$U$34:$W$43,3,0) -> 2250 | E8: =VLOOKUP(A8,[1]怪物!$R$3:$T$13,3,0) -> 30 | F8: =VLOOKUP(A8,$W:$AB,6,0) -> 8500 | H8: =$C$2&C$3&$D$2&C8&$E$2 -> {cd,3000} | I8: =$C$2&D$3&$D$2&D8&$E$2 -> {hp,2250} | J8: =$C$2&E$3&$D$2&E8&$E$2 -> {atk,30} | K8: =$C$2&F$3&$D$2&F8&$E$2 -> {spd,8500} | L8: =IF(VLOOKUP(A8,$W:$AC,7,0)=0,"",VLOOKUP(A8,$W:$AC,7,0)) | O8: ="["&_xlfn.TEXTJOIN(",",1,H8:M8)&"]" -> [{cd,3000},{hp,2250},{atk,30},{spd,8500}] | W8: 104 | AB8: 8500
A9: =Sheet1!E11 -> 101 | B9: =B4+1 -> 2 | C9: 3000 | D9: =VLOOKUP(B9,[1]怪物!$N$34:$Q$43,2,0) -> 60 | E9: =VLOOKUP(A9,[1]怪物!$N$3:$Q$13,4,0) -> 6 | F9: =VLOOKUP(A9,$W:$AB,6,0) -> 8500 | H9: =$C$2&C$3&$D$2&C9&$E$2 -> {cd,3000} | I9: =$C$2&D$3&$D$2&D9&$E$2 -> {hp,60} | J9: =$C$2&E$3&$D$2&E9&$E$2 -> {atk,6} | K9: =$C$2&F$3&$D$2&F9&$E$2 -> {spd,8500} | L9: =IF(VLOOKUP(A9,$W:$AC,7,0)=0,"",VLOOKUP(A9,$W:$AC,7,0)) | O9: ="["&_xlfn.TEXTJOIN(",",1,H9:M9)&"]" -> [{cd,3000},{hp,60},{atk,6},{spd,8500}] | W9: 105 | AA9: [60003] | AB9: 8500
A10: =Sheet1!E12 -> 100 | B10: =B5+1 -> 2 | C10: 3000 | D10: =VLOOKUP(B10,[1]怪物!$N$34:$Q$43,3,0) -> 50 | E10: =VLOOKUP(A10,[1]怪物!$N$3:$Q$13,4,0) -> 4 | F10: =VLOOKUP(A10,$W:$AB,6,0) -> 8500 | H10: =$C$2&C$3&$D$2&C10&$E$2 -> {cd,3000} | I10: =$C$2&D$3&$D$2&D10&$E$2 -> {hp,50} | J10: =$C$2&E$3&$D$2&E10&$E$2 -> {atk,4} | K10: =$C$2&F$3&$D$2&F10&$E$2 -> {spd,8500} | L10: =IF(VLOOKUP(A10,$W:$AC,7,0)=0,"",VLOOKUP(A10,$W:$AC,7,0)) | O10: ="["&_xlfn.TEXTJOIN(",",1,H10:M10)&"]" -> [{cd,3000},{hp,50},{atk,4},{spd,8500}] | W10: 106 | X10: 1 | Y10: 2002 | Z10: [{50012,6}] | AA10: [60002] | AB10: 8500
A11: =Sheet1!E13 -> 102 | B11: =B6+1 -> 2 | C11: 3000 | D11: =VLOOKUP(B11,[1]怪物!$N$34:$Q$43,4,0) -> 40 | E11: =VLOOKUP(A11,[1]怪物!$N$3:$Q$13,4,0) -> 3 | F11: =VLOOKUP(A11,$W:$AB,6,0) -> 8500 | H11: =$C$2&C$3&$D$2&C11&$E$2 -> {cd,3000} | I11: =$C$2&D$3&$D$2&D11&$E$2 -> {hp,40} | J11: =$C$2&E$3&$D$2&E11&$E$2 -> {atk,3} | K11: =$C$2&F$3&$D$2&F11&$E$2 -> {spd,8500} | L11: =IF(VLOOKUP(A11,$W:$AC,7,0)=0,"",VLOOKUP(A11,$W:$AC,7,0)) | O11: ="["&_xlfn.TEXTJOIN(",",1,H11:M11)&"]" -> [{cd,3000},{hp,40},{atk,3},{spd,8500}] | W11: 107 | X11: 1 | Z11: [{50013,6}] | AA11: [60004] | AB11: 8500
A12: =Sheet1!E14 -> 501 | B12: =B7+1 -> 2 | C12: 3000 | D12: =VLOOKUP(B12,[1]怪物!$U$34:$W$43,2,0) -> 1350 | E12: =VLOOKUP(A12,[1]怪物!$R$3:$T$13,2,0) -> 15 | F12: =VLOOKUP(A12,$W:$AB,6,0) -> 8500 | H12: =$C$2&C$3&$D$2&C12&$E$2 -> {cd,3000} | I12: =$C$2&D$3&$D$2&D12&$E$2 -> {hp,1350} | J12: =$C$2&E$3&$D$2&E12&$E$2 -> {atk,15} | K12: =$C$2&F$3&$D$2&F12&$E$2 -> {spd,8500} | L12: =IF(VLOOKUP(A12,$W:$AC,7,0)=0,"",VLOOKUP(A12,$W:$AC,7,0)) | O12: ="["&_xlfn.TEXTJOIN(",",1,H12:M12)&"]" -> [{cd,3000},{hp,1350},{atk,15},{spd,8500}] | W12: 108 | AB12: 8500
A13: =Sheet1!E15 -> 501 | B13: =B8+1 -> 2 | C13: 3000 | D13: =VLOOKUP(B13,[1]怪物!$U$34:$W$43,3,0) -> 2250 | E13: =VLOOKUP(A13,[1]怪物!$R$3:$T$13,3,0) -> 30 | F13: =VLOOKUP(A13,$W:$AB,6,0) -> 8500 | H13: =$C$2&C$3&$D$2&C13&$E$2 -> {cd,3000} | I13: =$C$2&D$3&$D$2&D13&$E$2 -> {hp,2250} | J13: =$C$2&E$3&$D$2&E13&$E$2 -> {atk,30} | K13: =$C$2&F$3&$D$2&F13&$E$2 -> {spd,8500} | L13: =IF(VLOOKUP(A13,$W:$AC,7,0)=0,"",VLOOKUP(A13,$W:$AC,7,0)) | O13: ="["&_xlfn.TEXTJOIN(",",1,H13:M13)&"]" -> [{cd,3000},{hp,2250},{atk,30},{spd,8500}] | W13: 109 | X13: 1 | Z13: [{50014,6}] | AB13: 8500
A14: =Sheet1!E16 -> 103 | B14: =B9+1 -> 3 | C14: 3000 | D14: =VLOOKUP(B14,[1]怪物!$N$34:$Q$43,2,0) -> 60 | E14: =VLOOKUP(A14,[1]怪物!$N$3:$Q$13,4,0) -> 6 | F14: =VLOOKUP(A14,$W:$AB,6,0) -> 8500 | H14: =$C$2&C$3&$D$2&C14&$E$2 -> {cd,3000} | I14: =$C$2&D$3&$D$2&D14&$E$2 -> {hp,60} | J14: =$C$2&E$3&$D$2&E14&$E$2 -> {atk,6} | K14: =$C$2&F$3&$D$2&F14&$E$2 -> {spd,8500} | L14: =IF(VLOOKUP(A14,$W:$AC,7,0)=0,"",VLOOKUP(A14,$W:$AC,7,0)) | O14: ="["&_xlfn.TEXTJOIN(",",1,H14:M14)&"]" -> [{cd,3000},{hp,60},{atk,6},{spd,8500}] | W14: 110 | AB14: 8500
A15: =Sheet1!E17 -> 104 | B15: =B10+1 -> 3 | C15: 3000 | D15: =VLOOKUP(B15,[1]怪物!$N$34:$Q$43,3,0) -> 50 | E15: =VLOOKUP(A15,[1]怪物!$N$3:$Q$13,4,0) -> 9 | F15: =VLOOKUP(A15,$W:$AB,6,0) -> 8500 | H15: =$C$2&C$3&$D$2&C15&$E$2 -> {cd,3000} | I15: =$C$2&D$3&$D$2&D15&$E$2 -> {hp,50} | J15: =$C$2&E$3&$D$2&E15&$E$2 -> {atk,9} | K15: =$C$2&F$3&$D$2&F15&$E$2 -> {spd,8500} | L15: =IF(VLOOKUP(A15,$W:$AC,7,0)=0,"",VLOOKUP(A15,$W:$AC,7,0)) | O15: ="["&_xlfn.TEXTJOIN(",",1,H15:M15)&"]" -> [{cd,3000},{hp,50},{atk,9},{spd,8500}] | W15: 111 | AB15: 8500
A16: =Sheet1!E18 -> 104 | B16: =B11+1 -> 3 | C16: 3000 | D16: =VLOOKUP(B16,[1]怪物!$N$34:$Q$43,4,0) -> 40 | E16: =VLOOKUP(A16,[1]怪物!$N$3:$Q$13,4,0) -> 9 | F16: =VLOOKUP(A16,$W:$AB,6,0) -> 8500 | H16: =$C$2&C$3&$D$2&C16&$E$2 -> {cd,3000} | I16: =$C$2&D$3&$D$2&D16&$E$2 -> {hp,40} | J16: =$C$2&E$3&$D$2&E16&$E$2 -> {atk,9} | K16: =$C$2&F$3&$D$2&F16&$E$2 -> {spd,8500} | L16: =IF(VLOOKUP(A16,$W:$AC,7,0)=0,"",VLOOKUP(A16,$W:$AC,7,0)) | O16: ="["&_xlfn.TEXTJOIN(",",1,H16:M16)&"]" -> [{cd,3000},{hp,40},{atk,9},{spd,8500}] | W16: 112 | X16: 1 | Z16: [{50015,6}] | AB16: 8500
A17: =Sheet1!E19 -> 504 | B17: =B12+1 -> 3 | C17: 3000 | D17: =VLOOKUP(B17,[1]怪物!$U$34:$W$43,2,0) -> 1350 | E17: =VLOOKUP(A17,[1]怪物!$R$3:$T$13,2,0) -> 22 | F17: =VLOOKUP(A17,$W:$AB,6,0) -> 8500 | H17: =$C$2&C$3&$D$2&C17&$E$2 -> {cd,3000} | I17: =$C$2&D$3&$D$2&D17&$E$2 -> {hp,1350} | J17: =$C$2&E$3&$D$2&E17&$E$2 -> {atk,22} | K17: =$C$2&F$3&$D$2&F17&$E$2 -> {spd,8500} | L17: =IF(VLOOKUP(A17,$W:$AC,7,0)=0,"",VLOOKUP(A17,$W:$AC,7,0)) | O17: ="["&_xlfn.TEXTJOIN(",",1,H17:M17)&"]" -> [{cd,3000},{hp,1350},{atk,22},{spd,8500}] | W17: 113 | X17: 1 | Z17: [{50016,6}] | AA17: [60005] | AB17: 8500
A18: =Sheet1!E20 -> 504 | B18: =B13+1 -> 3 | C18: 3000 | D18: =VLOOKUP(B18,[1]怪物!$U$34:$W$43,3,0) -> 2250 | E18: =VLOOKUP(A18,[1]怪物!$R$3:$T$13,3,0) -> 45 | F18: =VLOOKUP(A18,$W:$AB,6,0) -> 8500 | H18: =$C$2&C$3&$D$2&C18&$E$2 -> {cd,3000} | I18: =$C$2&D$3&$D$2&D18&$E$2 -> {hp,2250} | J18: =$C$2&E$3&$D$2&E18&$E$2 -> {atk,45} | K18: =$C$2&F$3&$D$2&F18&$E$2 -> {spd,8500} | L18: =IF(VLOOKUP(A18,$W:$AC,7,0)=0,"",VLOOKUP(A18,$W:$AC,7,0)) | O18: ="["&_xlfn.TEXTJOIN(",",1,H18:M18)&"]" -> [{cd,3000},{hp,2250},{atk,45},{spd,8500}] | W18: 114 | AB18: 8500
A19: =Sheet1!E21 -> 103 | B19: =B14+1 -> 4 | C19: 3000 | D19: =VLOOKUP(B19,[1]怪物!$N$34:$Q$43,2,0) -> 80 | E19: =VLOOKUP(A19,[1]怪物!$N$3:$Q$13,4,0) -> 6 | F19: =VLOOKUP(A19,$W:$AB,6,0) -> 8500 | H19: =$C$2&C$3&$D$2&C19&$E$2 -> {cd,3000} | I19: =$C$2&D$3&$D$2&D19&$E$2 -> {hp,80} | J19: =$C$2&E$3&$D$2&E19&$E$2 -> {atk,6} | K19: =$C$2&F$3&$D$2&F19&$E$2 -> {spd,8500} | L19: =IF(VLOOKUP(A19,$W:$AC,7,0)=0,"",VLOOKUP(A19,$W:$AC,7,0)) | O19: ="["&_xlfn.TEXTJOIN(",",1,H19:M19)&"]" -> [{cd,3000},{hp,80},{atk,6},{spd,8500}] | W19: 115 | AB19: 8500
A20: =Sheet1!E22 -> 104 | B20: =B15+1 -> 4 | C20: 3000 | D20: =VLOOKUP(B20,[1]怪物!$N$34:$Q$43,3,0) -> 70 | E20: =VLOOKUP(A20,[1]怪物!$N$3:$Q$13,4,0) -> 9 | F20: =VLOOKUP(A20,$W:$AB,6,0) -> 8500 | H20: =$C$2&C$3&$D$2&C20&$E$2 -> {cd,3000} | I20: =$C$2&D$3&$D$2&D20&$E$2 -> {hp,70} | J20: =$C$2&E$3&$D$2&E20&$E$2 -> {atk,9} | K20: =$C$2&F$3&$D$2&F20&$E$2 -> {spd,8500} | L20: =IF(VLOOKUP(A20,$W:$AC,7,0)=0,"",VLOOKUP(A20,$W:$AC,7,0)) | O20: ="["&_xlfn.TEXTJOIN(",",1,H20:M20)&"]" -> [{cd,3000},{hp,70},{atk,9},{spd,8500}] | W20: 116 | AA20: [60007] | AB20: 20000
A21: =Sheet1!E23 -> 106 | B21: =B16+1 -> 4 | C21: 3000 | D21: =VLOOKUP(B21,[1]怪物!$N$34:$Q$43,4,0) -> 60 | E21: =VLOOKUP(A21,[1]怪物!$N$3:$Q$13,4,0) -> 5 | F21: =VLOOKUP(A21,$W:$AB,6,0) -> 8500 | H21: =$C$2&C$3&$D$2&C21&$E$2 -> {cd,3000} | I21: =$C$2&D$3&$D$2&D21&$E$2 -> {hp,60} | J21: =$C$2&E$3&$D$2&E21&$E$2 -> {atk,5} | K21: =$C$2&F$3&$D$2&F21&$E$2 -> {spd,8500} | L21: =IF(VLOOKUP(A21,$W:$AC,7,0)=0,"",VLOOKUP(A21,$W:$AC,7,0)) | O21: ="["&_xlfn.TEXTJOIN(",",1,H21:M21)&"]" -> [{cd,3000},{hp,60},{atk,5},{spd,8500}] | W21: 117 | AB21: 8500 | AC21: {downUnderPhAtk,5000}
A22: =Sheet1!E24 -> 503 | B22: =B17+1 -> 4 | C22: 3000 | D22: =VLOOKUP(B22,[1]怪物!$U$34:$W$43,2,0) -> 1800 | E22: =VLOOKUP(A22,[1]怪物!$R$3:$T$13,2,0) -> 15 | F22: =VLOOKUP(A22,$W:$AB,6,0) -> 8500 | H22: =$C$2&C$3&$D$2&C22&$E$2 -> {cd,3000} | I22: =$C$2&D$3&$D$2&D22&$E$2 -> {hp,1800} | J22: =$C$2&E$3&$D$2&E22&$E$2 -> {atk,15} | K22: =$C$2&F$3&$D$2&F22&$E$2 -> {spd,8500} | L22: =IF(VLOOKUP(A22,$W:$AC,7,0)=0,"",VLOOKUP(A22,$W:$AC,7,0)) | O22: ="["&_xlfn.TEXTJOIN(",",1,H22:M22)&"]" -> [{cd,3000},{hp,1800},{atk,15},{spd,8500}] | W22: 118 | X22: 1 | Z22: [{50017,6}] | AA22: [60009] | AB22: 8500
A23: =Sheet1!E25 -> 503 | B23: =B18+1 -> 4 | C23: 3000 | D23: =VLOOKUP(B23,[1]怪物!$U$34:$W$43,3,0) -> 3000 | E23: =VLOOKUP(A23,[1]怪物!$R$3:$T$13,3,0) -> 30 | F23: =VLOOKUP(A23,$W:$AB,6,0) -> 8500 | H23: =$C$2&C$3&$D$2&C23&$E$2 -> {cd,3000} | I23: =$C$2&D$3&$D$2&D23&$E$2 -> {hp,3000} | J23: =$C$2&E$3&$D$2&E23&$E$2 -> {atk,30} | K23: =$C$2&F$3&$D$2&F23&$E$2 -> {spd,8500} | L23: =IF(VLOOKUP(A23,$W:$AC,7,0)=0,"",VLOOKUP(A23,$W:$AC,7,0)) | O23: ="["&_xlfn.TEXTJOIN(",",1,H23:M23)&"]" -> [{cd,3000},{hp,3000},{atk,30},{spd,8500}] | W23: 119 | X23: 1 | Z23: [{50018,6}] | AB23: 8500 | AC23: {downUnderMagicAtk,5000}
A24: =Sheet1!E26 -> 100 | B24: =B19+1 -> 5 | C24: 3000 | D24: =VLOOKUP(B24,[1]怪物!$N$34:$Q$43,2,0) -> 100 | E24: =VLOOKUP(A24,[1]怪物!$N$3:$Q$13,4,0) -> 4 | F24: =VLOOKUP(A24,$W:$AB,6,0) -> 8500 | H24: =$C$2&C$3&$D$2&C24&$E$2 -> {cd,3000} | I24: =$C$2&D$3&$D$2&D24&$E$2 -> {hp,100} | J24: =$C$2&E$3&$D$2&E24&$E$2 -> {atk,4} | K24: =$C$2&F$3&$D$2&F24&$E$2 -> {spd,8500} | L24: =IF(VLOOKUP(A24,$W:$AC,7,0)=0,"",VLOOKUP(A24,$W:$AC,7,0)) | O24: ="["&_xlfn.TEXTJOIN(",",1,H24:M24)&"]" -> [{cd,3000},{hp,100},{atk,4},{spd,8500}] | W24: 120 | AB24: 8500
A25: =Sheet1!E27 -> 102 | B25: =B20+1 -> 5 | C25: 3000 | D25: =VLOOKUP(B25,[1]怪物!$N$34:$Q$43,3,0) -> 90 | E25: =VLOOKUP(A25,[1]怪物!$N$3:$Q$13,4,0) -> 3 | F25: =VLOOKUP(A25,$W:$AB,6,0) -> 8500 | H25: =$C$2&C$3&$D$2&C25&$E$2 -> {cd,3000} | I25: =$C$2&D$3&$D$2&D25&$E$2 -> {hp,90} | J25: =$C$2&E$3&$D$2&E25&$E$2 -> {atk,3} | K25: =$C$2&F$3&$D$2&F25&$E$2 -> {spd,8500} | L25: =IF(VLOOKUP(A25,$W:$AC,7,0)=0,"",VLOOKUP(A25,$W:$AC,7,0)) | O25: ="["&_xlfn.TEXTJOIN(",",1,H25:M25)&"]" -> [{cd,3000},{hp,90},{atk,3},{spd,8500}] | W25: 121 | AB25: 8500 | AC25: {firingDmgDown,5000}
A26: =Sheet1!E28 -> 105 | B26: =B21+1 -> 5 | C26: 3000 | D26: =VLOOKUP(B26,[1]怪物!$N$34:$Q$43,4,0) -> 80 | E26: =VLOOKUP(A26,[1]怪物!$N$3:$Q$13,4,0) -> 6 | F26: =VLOOKUP(A26,$W:$AB,6,0) -> 8500 | H26: =$C$2&C$3&$D$2&C26&$E$2 -> {cd,3000} | I26: =$C$2&D$3&$D$2&D26&$E$2 -> {hp,80} | J26: =$C$2&E$3&$D$2&E26&$E$2 -> {atk,6} | K26: =$C$2&F$3&$D$2&F26&$E$2 -> {spd,8500} | L26: =IF(VLOOKUP(A26,$W:$AC,7,0)=0,"",VLOOKUP(A26,$W:$AC,7,0)) | O26: ="["&_xlfn.TEXTJOIN(",",1,H26:M26)&"]" -> [{cd,3000},{hp,80},{atk,6},{spd,8500}] | W26: 122 | AA26: [60011,60012] | AB26: 8500
A27: =Sheet1!E29 -> 502 | B27: =B22+1 -> 5 | C27: 3000 | D27: =VLOOKUP(B27,[1]怪物!$U$34:$W$43,2,0) -> 2250 | E27: =VLOOKUP(A27,[1]怪物!$R$3:$T$13,2,0) -> 10 | F27: =VLOOKUP(A27,$W:$AB,6,0) -> 8500 | H27: =$C$2&C$3&$D$2&C27&$E$2 -> {cd,3000} | I27: =$C$2&D$3&$D$2&D27&$E$2 -> {hp,2250} | J27: =$C$2&E$3&$D$2&E27&$E$2 -> {atk,10} | K27: =$C$2&F$3&$D$2&F27&$E$2 -> {spd,8500} | L27: =IF(VLOOKUP(A27,$W:$AC,7,0)=0,"",VLOOKUP(A27,$W:$AC,7,0)) | O27: ="["&_xlfn.TEXTJOIN(",",1,H27:M27)&"]" -> [{cd,3000},{hp,2250},{atk,10},{spd,8500}] | W27: 123 | X27: 1 | Z27: [{50019,6}] | AA27: [60010] | AB27: 8500
A28: =Sheet1!E30 -> 500 | B28: =B23+1 -> 5 | C28: 3000 | D28: =VLOOKUP(B28,[1]怪物!$U$34:$W$43,3,0) -> 3750 | E28: =VLOOKUP(A28,[1]怪物!$R$3:$T$13,3,0) -> 20 | F28: =VLOOKUP(A28,$W:$AB,6,0) -> 8500 | H28: =$C$2&C$3&$D$2&C28&$E$2 -> {cd,3000} | I28: =$C$2&D$3&$D$2&D28&$E$2 -> {hp,3750} | J28: =$C$2&E$3&$D$2&E28&$E$2 -> {atk,20} | K28: =$C$2&F$3&$D$2&F28&$E$2 -> {spd,8500} | L28: =IF(VLOOKUP(A28,$W:$AC,7,0)=0,"",VLOOKUP(A28,$W:$AC,7,0)) | O28: ="["&_xlfn.TEXTJOIN(",",1,H28:M28)&"]" -> [{cd,3000},{hp,3750},{atk,20},{spd,8500}] | W28: 124 | AA28: [60013] | AB28: 8500 | AC28: {downCritDmg,5000},{resRate,2000}
A29: =Sheet1!E31 -> 100 | B29: =B24+1 -> 6 | C29: 3000 | D29: =VLOOKUP(B29,[1]怪物!$N$34:$Q$43,2,0) -> 120 | E29: =VLOOKUP(A29,[1]怪物!$N$3:$Q$13,4,0) -> 4 | F29: =VLOOKUP(A29,$W:$AB,6,0) -> 8500 | H29: =$C$2&C$3&$D$2&C29&$E$2 -> {cd,3000} | I29: =$C$2&D$3&$D$2&D29&$E$2 -> {hp,120} | J29: =$C$2&E$3&$D$2&E29&$E$2 -> {atk,4} | K29: =$C$2&F$3&$D$2&F29&$E$2 -> {spd,8500} | L29: =IF(VLOOKUP(A29,$W:$AC,7,0)=0,"",VLOOKUP(A29,$W:$AC,7,0)) | O29: ="["&_xlfn.TEXTJOIN(",",1,H29:M29)&"]" -> [{cd,3000},{hp,120},{atk,4},{spd,8500}] | W29: 125 | AA29: [60016] | AB29: 8500
A30: =Sheet1!E32 -> 105 | B30: =B25+1 -> 6 | C30: 3000 | D30: =VLOOKUP(B30,[1]怪物!$N$34:$Q$43,3,0) -> 110 | E30: =VLOOKUP(A30,[1]怪物!$N$3:$Q$13,4,0) -> 6 | F30: =VLOOKUP(A30,$W:$AB,6,0) -> 8500 | H30: =$C$2&C$3&$D$2&C30&$E$2 -> {cd,3000} | I30: =$C$2&D$3&$D$2&D30&$E$2 -> {hp,110} | J30: =$C$2&E$3&$D$2&E30&$E$2 -> {atk,6} | K30: =$C$2&F$3&$D$2&F30&$E$2 -> {spd,8500} | L30: =IF(VLOOKUP(A30,$W:$AC,7,0)=0,"",VLOOKUP(A30,$W:$AC,7,0)) | O30: ="["&_xlfn.TEXTJOIN(",",1,H30:M30)&"]" -> [{cd,3000},{hp,110},{atk,6},{spd,8500}] | W30: 126 | X30: 1 | Z30: [{50031,6}] | AA30: [60014] | AB30: 8500 | AC30: {miss,1500}
A31: =Sheet1!E33 -> 102 | B31: =B26+1 -> 6 | C31: 3000 | D31: =VLOOKUP(B31,[1]怪物!$N$34:$Q$43,4,0) -> 100 | E31: =VLOOKUP(A31,[1]怪物!$N$3:$Q$13,4,0) -> 3 | F31: =VLOOKUP(A31,$W:$AB,6,0) -> 8500 | H31: =$C$2&C$3&$D$2&C31&$E$2 -> {cd,3000} | I31: =$C$2&D$3&$D$2&D31&$E$2 -> {hp,100} | J31: =$C$2&E$3&$D$2&E31&$E$2 -> {atk,3} | K31: =$C$2&F$3&$D$2&F31&$E$2 -> {spd,8500} | L31: =IF(VLOOKUP(A31,$W:$AC,7,0)=0,"",VLOOKUP(A31,$W:$AC,7,0)) | O31: ="["&_xlfn.TEXTJOIN(",",1,H31:M31)&"]" -> [{cd,3000},{hp,100},{atk,3},{spd,8500}] | W31: 127 | AA31: [60015] | AB31: 8500
A32: =Sheet1!E34 -> 502 | B32: =B27+1 -> 6 | C32: 3000 | D32: =VLOOKUP(B32,[1]怪物!$U$34:$W$43,2,0) -> 2700 | E32: =VLOOKUP(A32,[1]怪物!$R$3:$T$13,2,0) -> 10 | F32: =VLOOKUP(A32,$W:$AB,6,0) -> 8500 | H32: =$C$2&C$3&$D$2&C32&$E$2 -> {cd,3000} | I32: =$C$2&D$3&$D$2&D32&$E$2 -> {hp,2700} | J32: =$C$2&E$3&$D$2&E32&$E$2 -> {atk,10} | K32: =$C$2&F$3&$D$2&F32&$E$2 -> {spd,8500} | L32: =IF(VLOOKUP(A32,$W:$AC,7,0)=0,"",VLOOKUP(A32,$W:$AC,7,0)) | O32: ="["&_xlfn.TEXTJOIN(",",1,H32:M32)&"]" -> [{cd,3000},{hp,2700},{atk,10},{spd,8500}] | W32: 128 | AA32: [60017] | AB32: 8500 | AC32: {upUnderPhAtk,8000}
A33: =Sheet1!E35 -> 502 | B33: =B28+1 -> 6 | C33: 3000 | D33: =VLOOKUP(B33,[1]怪物!$U$34:$W$43,3,0) -> 4500 | E33: =VLOOKUP(A33,[1]怪物!$R$3:$T$13,3,0) -> 21 | F33: =VLOOKUP(A33,$W:$AB,6,0) -> 8500 | H33: =$C$2&C$3&$D$2&C33&$E$2 -> {cd,3000} | I33: =$C$2&D$3&$D$2&D33&$E$2 -> {hp,4500} | J33: =$C$2&E$3&$D$2&E33&$E$2 -> {atk,21} | K33: =$C$2&F$3&$D$2&F33&$E$2 -> {spd,8500} | L33: =IF(VLOOKUP(A33,$W:$AC,7,0)=0,"",VLOOKUP(A33,$W:$AC,7,0)) | O33: ="["&_xlfn.TEXTJOIN(",",1,H33:M33)&"]" -> [{cd,3000},{hp,4500},{atk,21},{spd,8500}] | W33: 129 | AB33: 8500
A34: =Sheet1!E36 -> 104 | B34: =B29+1 -> 7 | C34: 3000 | D34: =VLOOKUP(B34,[1]怪物!$N$34:$Q$43,2,0) -> 140 | E34: =VLOOKUP(A34,[1]怪物!$N$3:$Q$13,4,0) -> 9 | F34: =VLOOKUP(A34,$W:$AB,6,0) -> 8500 | H34: =$C$2&C$3&$D$2&C34&$E$2 -> {cd,3000} | I34: =$C$2&D$3&$D$2&D34&$E$2 -> {hp,140} | J34: =$C$2&E$3&$D$2&E34&$E$2 -> {atk,9} | K34: =$C$2&F$3&$D$2&F34&$E$2 -> {spd,8500} | L34: =IF(VLOOKUP(A34,$W:$AC,7,0)=0,"",VLOOKUP(A34,$W:$AC,7,0)) | O34: ="["&_xlfn.TEXTJOIN(",",1,H34:M34)&"]" -> [{cd,3000},{hp,140},{atk,9},{spd,8500}] | W34: 500 | Y34: 2001 | AA34: [60002] | AB34: 8500
A35: =Sheet1!E37 -> 106 | B35: =B30+1 -> 7 | C35: 3000 | D35: =VLOOKUP(B35,[1]怪物!$N$34:$Q$43,3,0) -> 130 | E35: =VLOOKUP(A35,[1]怪物!$N$3:$Q$13,4,0) -> 5 | F35: =VLOOKUP(A35,$W:$AB,6,0) -> 8500 | H35: =$C$2&C$3&$D$2&C35&$E$2 -> {cd,3000} | I35: =$C$2&D$3&$D$2&D35&$E$2 -> {hp,130} | J35: =$C$2&E$3&$D$2&E35&$E$2 -> {atk,5} | K35: =$C$2&F$3&$D$2&F35&$E$2 -> {spd,8500} | L35: =IF(VLOOKUP(A35,$W:$AC,7,0)=0,"",VLOOKUP(A35,$W:$AC,7,0)) | O35: ="["&_xlfn.TEXTJOIN(",",1,H35:M35)&"]" -> [{cd,3000},{hp,130},{atk,5},{spd,8500}] | W35: 501 | AB35: 8500
A36: =Sheet1!E38 -> 107 | B36: =B31+1 -> 7 | C36: 3000 | D36: =VLOOKUP(B36,[1]怪物!$N$34:$Q$43,4,0) -> 120 | E36: =VLOOKUP(A36,[1]怪物!$N$3:$Q$13,4,0) -> 4 | F36: =VLOOKUP(A36,$W:$AB,6,0) -> 8500 | H36: =$C$2&C$3&$D$2&C36&$E$2 -> {cd,3000} | I36: =$C$2&D$3&$D$2&D36&$E$2 -> {hp,120} | J36: =$C$2&E$3&$D$2&E36&$E$2 -> {atk,4} | K36: =$C$2&F$3&$D$2&F36&$E$2 -> {spd,8500} | L36: =IF(VLOOKUP(A36,$W:$AC,7,0)=0,"",VLOOKUP(A36,$W:$AC,7,0)) | O36: ="["&_xlfn.TEXTJOIN(",",1,H36:M36)&"]" -> [{cd,3000},{hp,120},{atk,4},{spd,8500}] | W36: 502 | X36: 1 | Z36: [{50021,6}] | AB36: 8500
A37: =Sheet1!E39 -> 503 | B37: =B32+1 -> 7 | C37: 3000 | D37: =VLOOKUP(B37,[1]怪物!$U$34:$W$43,2,0) -> 3150 | E37: =VLOOKUP(A37,[1]怪物!$R$3:$T$13,2,0) -> 15 | F37: =VLOOKUP(A37,$W:$AB,6,0) -> 8500 | H37: =$C$2&C$3&$D$2&C37&$E$2 -> {cd,3000} | I37: =$C$2&D$3&$D$2&D37&$E$2 -> {hp,3150} | J37: =$C$2&E$3&$D$2&E37&$E$2 -> {atk,15} | K37: =$C$2&F$3&$D$2&F37&$E$2 -> {spd,8500} | L37: =IF(VLOOKUP(A37,$W:$AC,7,0)=0,"",VLOOKUP(A37,$W:$AC,7,0)) | O37: ="["&_xlfn.TEXTJOIN(",",1,H37:M37)&"]" -> [{cd,3000},{hp,3150},{atk,15},{spd,8500}] | W37: 503 | AA37: [60001] | AB37: 8500
A38: =Sheet1!E40 -> 503 | B38: =B33+1 -> 7 | C38: 3000 | D38: =VLOOKUP(B38,[1]怪物!$U$34:$W$43,3,0) -> 5250 | E38: =VLOOKUP(A38,[1]怪物!$R$3:$T$13,3,0) -> 30 | F38: =VLOOKUP(A38,$W:$AB,6,0) -> 8500 | H38: =$C$2&C$3&$D$2&C38&$E$2 -> {cd,3000} | I38: =$C$2&D$3&$D$2&D38&$E$2 -> {hp,5250} | J38: =$C$2&E$3&$D$2&E38&$E$2 -> {atk,30} | K38: =$C$2&F$3&$D$2&F38&$E$2 -> {spd,8500} | L38: =IF(VLOOKUP(A38,$W:$AC,7,0)=0,"",VLOOKUP(A38,$W:$AC,7,0)) | O38: ="["&_xlfn.TEXTJOIN(",",1,H38:M38)&"]" -> [{cd,3000},{hp,5250},{atk,30},{spd,8500}] | W38: 504 | AB38: 8500
A39: =Sheet1!E41 -> 103 | B39: =B34+1 -> 8 | C39: 3000 | D39: =VLOOKUP(B39,[1]怪物!$N$34:$Q$43,2,0) -> 160 | E39: =VLOOKUP(A39,[1]怪物!$N$3:$Q$13,4,0) -> 6 | F39: =VLOOKUP(A39,$W:$AB,6,0) -> 8500 | H39: =$C$2&C$3&$D$2&C39&$E$2 -> {cd,3000} | I39: =$C$2&D$3&$D$2&D39&$E$2 -> {hp,160} | J39: =$C$2&E$3&$D$2&E39&$E$2 -> {atk,6} | K39: =$C$2&F$3&$D$2&F39&$E$2 -> {spd,8500} | L39: =IF(VLOOKUP(A39,$W:$AC,7,0)=0,"",VLOOKUP(A39,$W:$AC,7,0)) | O39: ="["&_xlfn.TEXTJOIN(",",1,H39:M39)&"]" -> [{cd,3000},{hp,160},{atk,6},{spd,8500}] | W39: 505 | AB39: 8500
A40: =Sheet1!E42 -> 107 | B40: =B35+1 -> 8 | C40: 3000 | D40: =VLOOKUP(B40,[1]怪物!$N$34:$Q$43,3,0) -> 150 | E40: =VLOOKUP(A40,[1]怪物!$N$3:$Q$13,4,0) -> 4 | F40: =VLOOKUP(A40,$W:$AB,6,0) -> 8500 | H40: =$C$2&C$3&$D$2&C40&$E$2 -> {cd,3000} | I40: =$C$2&D$3&$D$2&D40&$E$2 -> {hp,150} | J40: =$C$2&E$3&$D$2&E40&$E$2 -> {atk,4} | K40: =$C$2&F$3&$D$2&F40&$E$2 -> {spd,8500} | L40: =IF(VLOOKUP(A40,$W:$AC,7,0)=0,"",VLOOKUP(A40,$W:$AC,7,0)) | O40: ="["&_xlfn.TEXTJOIN(",",1,H40:M40)&"]" -> [{cd,3000},{hp,150},{atk,4},{spd,8500}] | W40: 506 | X40: 1 | Y40: 2002 | Z40: [{50022,6}] | AA40: [60002] | AB40: 8500
...

Sheet Sheet3
